Workbook

Sheet Analisi E27 — MAN
A1: Analisi IACS UR E27 (sez. 4.1 + 4.2 + sez. 3 + sez. 5 SDLC) — MAN Energy Solutions / Everllence (sistema PrimeServ Assist + CEON) — GNV
A2: HWG Sababa — Aprile 2026 (v0.0.3) | Fonti: 3. PSA Installation Guide v1.5.pdf (giugno 2023, MAN PrimeServ Digital Denmark), 1. Network overview for CEON connectivity.pdf, 2. Connectivity to CEON - Firewall requirements.pdf (set-up instruction 6097175-5, rev. 02 ott 2022), Everllence_Standard_ATU-mGuard_Network_REV02.pdf (rev. 02 del 04/06/2025, SAP Nr. 10004096219), Everllence_connectivity_checklist_PSA_ATU_REV02.pdf, Everllence_connectivity_checklist_PSA_mGuard_ATU.pdf, Everllence_connectivity_checklist_PSA_mGuard_DLM.pdf, connectivity_checklist_PSA_mGuard_DLM_V3.pdf, Architecture.png, CEON-Security.png, infographic.png, Network.txt (config switch nave: VLAN 1, MAC a8:74:1d:f2:2a:77, switch VIR-DIS16-DK2-MVZ5 interface 3/1/21), Pentest2025redacted.pdf (Mya CEON Security Assessment & Retest, Project No. 507.2503, Recurity Labs GmbH, ottobre 2025, 110 pagine totali, scope: PrimeServ Assist Mobile App + Web Apps + AWS Infrastructure), Cyber Security Questionnaires - Whistic - 2024.01.xlsx (questionario standard MAN ES, response del 01/07/2024, 577 Q&A su 3 framework: SIG Lite Shared Assessment 351 Q&A, CAIQ Lite CSA Cloud 130 Q&A, NIST CSF 114 Q&A), RedactedPentest.pdf (API Services Retest, Project No. 241.2305, Recurity Labs GmbH, dicembre 2023, 45 pagine totali, 12 retested findings ai capitoli 3.1-3.12)., Security FAQ_v3.docx (FAQ ufficiali MAN-CEON Data Security, Privacy and Compliance), ISMS ATU Release Management.pdf (release management policy CEON ATU/Agent Shell/Agent Core/Ubuntu Core), B&R_APC2200_UserManual_ENG_V2.02.pdf (manuale hardware ATU - PC Bernecker & Rainer), (standard) MAN ES_13.1_en_Instruction_1.pdf (manuale operativo standard MAN ES), SMARTSHIP software CEON.pdf (Bureau Veritas Type Approval certificate 82605/A0 per Everllence CEON portal v2.57.1, valido fino al 10/12/2030), Final Certificate MAN Energy Solutions-4181-01.pdf (ISO/IEC 27001:2022 ISMS-4181-01, scope MAN CEON platform, valido 22/11/2024-21/11/2027), CyberEssentialsCertificate2025.pdf + 25-26-CyberEssentials.pdf (UK Cyber Essentials, scope multi-site Augsburg/Copenhagen/Frederikshavn/Holeby/Madrid/Stockport/Kintore/Redhill), System_and_Organization_Controls_(SOC)_2_Report.pdf (SOC 2 Type II AWS underlying infrastructure, periodo 01/10/2022-30/09/2023), 4306569_4307373_RAC_20220628.pdf, T2489161 PDA approval_147491652.pdf, 24-2489161-PDA.pdf, Certificate_20230714.pdf, ISO_9001 + ISO_14001 + ISO_45001 (certificazioni gestione qualità/ambiente/safety MAN ES, valide al 26/06/2024). FOTO ARMADI INSTALLAZIONE A BORDO (MAN pt.2): 20260223_163647.jpg + 20260223_163650.jpg (close-up mGuard rs4000 S/N 3024009333 label 85D1 con switch managed MAN, alimentatore Phoenix Contact 85G1 e fusibili 85F102/85F111, scattate il 23/02/2026 alle 16:36:47 e 16:36:50), IMG_6050.JPG + IMG_6051.JPG + IMG_6053.JPG (postazione differente: mGuard rs4000 S/N 3024007756 label 85D1 con Weidmüller Ethernet Switch 85D2, Phoenix Contact QUINT POWER 85G1 24V 3.5A, relè Finder K3204, magnetotermici ABB 85F1, cavi etichettati MES/PHNI BUF/GN VZN), IMG_6059.JPG (armadio MAN 'RAC - REMOTE ACCESS CABINET' n. 4307373, Rittal enclosure, fronte armadio con LED 'REMOTE ACCESS READY' verde acceso, LED 'REMOTE ACCESS CONNECTED' bianco, SELETTORE A CHIAVE 'REMOTE ACCESS OFF/ON' a 3 posizioni e pulsante 'LAMP TEST'). Per i criteri di classificazione stati, vedere foglio 'Legenda'.
A3: # | B3: Controllo E27 | C3: Rif. IEC | D3: Cosa sappiamo | E3: Da dove viene l'informazione | F3: Stato | G3: Cosa manca / criticità | H3: Cosa fare | I3: Priorità
A4: FR1 — Identificazione e autenticazione
A5: 1 | B5: Identificazione utente | C5: SR 1.1 | D5: MAN-CEON usa metodi di autenticazione robusti per restringere l'accesso ai dispositivi solo a utenti autorizzati (Security FAQ_v3.docx, sez. 'How does MAN-ES ensure that data access is protected from unauthorized access'). MFA implementata per utenti umani sulla piattaforma cloud CEON. Asset-based Access Control con segmentazione e need-to-know (CEON-Security.png punto 8). Asset and User On-boarding con processi formali documentati (CEON-Security.png punto 9). L'ATU (Linux/Windows-based) sul sito cliente espone interfaccia management; identificazione utenti gestita via piattaforma CEON. DA POLICY MAN ES 13.1 sez. 5 (Information Security): 'All systems connected to the MAN ES network (internal network) must be authenticated via secure, verifiable connections. Secure authentication procedures shall be used.' L'autenticazione è obbligatoria per tutti i sistemi connessi alla rete MAN; per i sistemi cliente come l'ATU CEON sulla nave GNV vale lo stesso principio. DA POLICY MAN ES 13.1 Articolo 16 'Management of authorizations and passwords' punto (2): 'A formal procedure shall be established for the registration and de-registration of users. Registrations and de-registrations carried out shall be documented in auditable form'. Articolo 18 punto (8): 'All access to systems containing sensitive data or functions shall be safeguarded with access control where the identity of the user is determined'. Identificazione utente obbligatoria a livello policy MAN su tutti i sistemi sensibili. | E5: Security FAQ_v3.docx (sez. Data access protection) CEON-Security.png punti 8-9 Architecture.png (standard) MAN ES_13.1_en_Instruction_1.pdf (Group Policy Information Security, applicable as of 01/03/2023), sez. 5 punto (8) (standard) MAN ES_13.1_en_Instruction_1.pdf, Art. 16 punto (2), Art. 18 punto (8) | F5: CONFORME | G5: Identificazione utente coperta multi-livello: MFA confermata su CEON cloud (Whistic IAM-14.1) + procedura formale di registration/de-registration utenti documentabile (MAN ES 13.1 Art. 16 punto 2) + obbligo accesso autenticato a tutti i sistemi sensibili (Art. 18 punto 8) + requisito strong authentication su tutta la rete MAN (Art. 13 punto 8). | H5: Verificare on-site sui PC ATU GNV: utenti locali presenti, integrazione Active Directory (se applicabile). | I5: BASSA
A6: 2 | B6: Gestione account | C6: SR 1.3 | D6: Asset and User On-boarding con processi ben definiti per data model & connectivity setup e user on/offboarding (CEON-Security.png punto 9). Procedure di provisioning utenti su CEON cloud allineate a ISO 27001 (ISMS-4181-01). DA POLICY MAN ES 13.1: 'Privileged user accounts shall not be used for everyday work' (sez. 5, gestione utenti privilegiati). Principio di separazione tra account daily-use e account privilegiati implementato a livello policy aziendale MAN. DA POLICY MAN ES 13.1 Articolo 16 punto (6): 'Existing access authorizations shall be reviewed at regular intervals. These intervals shall be determined according to the extent and criticality of the access'. Articolo 9 'The hiring, change to the appointment or termination of personnel': 'In the event of hiring, change to appointment or retirement of personnel, information, plant equipment, devices, and systems are immediately returned to MAN ES and entry and access rights are immediately revoked. This shall also apply to service providers'. Account lifecycle management completo a livello policy aziendale. | E6: CEON-Security.png punto 9 Final Certificate MAN Energy Solutions-4181-01.pdf (ISO/IEC 27001:2022) (standard) MAN ES_13.1_en_Instruction_1.pdf (Group Policy Information Security, applicable as of 01/03/2023), sez. 5 punto (4) (standard) MAN ES_13.1_en_Instruction_1.pdf, Art. 9 + Art. 16 punto (6) | F6: CONFORME | G6: Account lifecycle completamente coperto: creazione/modifica/cessazione account immediata con revoca rights (MAN ES 13.1 Art. 9), procedura formale registration/de-registration documentata in forma audit (Art. 16 punto 2), review periodica delle authorizations a intervalli determinati per criticità (Art. 16 punto 6). | H6: Nessuna azione necessaria; eventuale verifica di una sample report di account review può essere richiesta al fornitore (Whistic H.0.5). | I6: BASSA
A7: 3 | B7: Gestione ruoli | C7: SR 1.4 | D7: Asset-based Access Control con strict segmentation e need-to-know principle (CEON-Security.png punto 8). Modello di autorizzazione granulare (CEON-Security.png punto 10) per minimizzare incidenti di sicurezza. DA POLICY MAN ES 13.1 Articolo 16 punto (1): 'A technical policy for access rights shall be established and verified regularly based on business and security requirements'. Punto (3): 'The allocation of administrative system authorizations shall be carried out restrictively, documented with care, and verified on a regular basis'. Articolo 1 'Segregation of duties and responsibilities': 'tasks and responsibilities in business processes together with critical functions shall be identified and evaluated... The misuse and manipulation of information and IT systems shall be prevented to the greatest possible extent through the separation of tasks'. | E7: CEON-Security.png punti 8, 10 Final Certificate ISO/IEC 27001:2022 ISMS-4181-01 (standard) MAN ES_13.1_en_Instruction_1.pdf, Art. 1 + Art. 16 punti (1),(3) | F7: CONFORME | G7: Modello a ruoli formalmente strutturato: segregation of duties (MAN ES 13.1 Art. 1) + technical policy access rights con review periodica (Art. 16 punto 1) + minimum/adequate authorization principle (Art. 16 punto 2) + admin authorizations restricted/documented (Art. 16 punto 3) + supervisor non può essere admin nello stesso scope (Art. 8 punto 2). | H7: Nessuna azione strettamente necessaria; matrice ruoli/permessi tecnica specifica del prodotto CEON può essere richiesta in fase di operations setup. | I7: BASSA
A8: 4 | B8: Gestione credenziali | C8: SR 1.5 | D8: Secure key management implementato (Security FAQ_v3.docx). Gestione chiavi crittografiche tramite AWS Key Management Service (KMS) con envelope encryption (Security FAQ_v3.docx, sez. cryptographic keys protection). Master keys protette via AWS KMS. Secure outbound connection only (CEON-Security.png punto 5). DA WHISTIC SIG LITE H.2: 'Has management approved, communicated, and enforced a password policy for systems that transmit, process, or store scoped data on all platforms?' → YES. DA WHISTIC SIG LITE H.2.1: 'Does the password policy require keeping passwords confidential?' → YES. DA WHISTIC SIG LITE H.0.2: 'Corporate password policy and procedures documentation' → 'Available upon request'. DA WHISTIC SIG LITE N.12: 'Are default passwords changed or disabled prior to placing network devices into production?' → YES. DA POLICY MAN ES 13.1: 'Password management stipulations shall be defined centrally and shall be evaluated on a regular basis and be implemented in accordance' (sez. 5 punto 5). Gestione centralizzata delle password con evaluation periodica formalmente prescritta dalla policy aziendale MAN ES. DA POLICY MAN ES 13.1 Articolo 16 punto (5): 'Password management stipulations shall be defined centrally and shall be evaluated on a regular basis and be implemented in accordance with the requirements of developing technologies. Passwords shall be managed in accordance with documented procedures'. Password management centralizzato e con valutazione periodica e procedure documentate a livello policy. | E8: Security FAQ_v3.docx (sez. Cryptographic keys protection) CEON-Security.png punto 5 Architecture.png Cyber Security Questionnaires - Whistic - 2024.01.xlsx sez. H.2, H.2.1, H.0.2, N.12 (standard) MAN ES_13.1_en_Instruction_1.pdf (Group Policy Information Security, applicable as of 01/03/2023), sez. 5 punto (5) (standard) MAN ES_13.1_en_Instruction_1.pdf, Art. 16 punto (5) | F8: PARZIALMENTE CONFORME | G8: Gestione credenziali utente CEON cloud presumibilmente robusta (ISO 27001 alignment). Manca dettaglio operativo: policy password, rotation periodica, password storage hash function (bcrypt? argon2?), procedure di reset password. | H8: Richiedere a MAN/Everllence: policy password formale (min length, complexity, history, expiry), procedure reset password sicure, esistenza forced password change al primo login. | I8: MEDIA
A9: 5 | B9: Accesso wireless | C9: SR 1.6 | D9: L'ATU CEON è un Hardened Device con wireless DISABILITATO (CEON-Security.png punto 1: 'No interaction possible from outside (wireless, usb, ssh disabled) / DNV certified'). Hardware B&R APC2200 industrial PC. Network ATU configurato via cavo Ethernet (RJ45 STP CAT6 minimo) verso managed switch MAN. | E9: CEON-Security.png punto 1 B&R_APC2200_UserManual_ENG_V2.02.pdf 3. PSA Installation Guide v1.5.pdf | F9: CONFORME | G9: Wireless dichiarato disabilitato by design su ATU. DNV certified come Hardened Device. Confermare nave per nave durante visita on-site che effettivamente non ci siano dongle Wi-Fi/Bluetooth o adapter abilitati. | H9: Verifica visiva on-site sui PC ATU GNV: assenza adapter wireless attivi, conferma BIOS lock di interfacce wireless. | I9: BASSA
A10: 6 | B10: Robustezza password | C10: SR 1.7 | D10: Robustezza password gestita lato CEON cloud (AWS) con allineamento ISO 27001:2022 ISMS-4181-01. Aspetto specifico non dettagliato nei documenti tecnici disponibili. DA WHISTIC SIG LITE H.2: password policy approvata e enforced (YES). Dettaglio specifico (lunghezza minima, complessità, expiry) disponibile a richiesta tramite Whistic H.0.2 'Corporate password policy and procedures documentation: Available upon request'. | E10: Final Certificate ISO/IEC 27001:2022 ISMS-4181-01 Security FAQ_v3.docx (riferimenti generali sicurezza) Cyber Security Questionnaires - Whistic - 2024.01.xlsx sez. H.2, H.0.2 | F10: PARZIALMENTE CONFORME | G10: Password policy esiste ed è enforced. Manca documento formale dettagliato (richiedibile a MAN via canale ufficiale). | H10: Richiedere a MAN tramite Whistic platform il documento 'Corporate password policy and procedures' (riferimento Whistic H.0.2). | I10: MEDIA
A11: 7 | B11: Mascheratura password | C11: SR 1.10 | D11: Best practice standard per applicazioni web moderne; CEON è SaaS hosted su AWS con UI web/mobile. | E11: Architecture.png Security FAQ_v3.docx (UI HTTPS) | F11: PARZIALMENTE CONFORME | G11: Mascheratura password durante input è prassi standard ma non documentata esplicitamente. Da confermare visivamente. | H11: Verifica visiva durante demo CEON cloud UI: campo password mascherato, no echo plaintext. | I11: BASSA
A12: FR2 — Controllo degli accessi e audit
A13: 8 | B13: Minimo privilegio | C13: SR 2.1 | D13: Asset-based Access Control con strict segmentation e need-to-know principle (CEON-Security.png punto 8). Modello di autorizzazione granulare per minimizzare incidenti di sicurezza (punto 10). ISO 27001 ISMS implementa principle of least privilege come parte dei controlli A.5/A.8. DA POLICY MAN ES 13.1: 'It shall be ensured that users only receive authorisations effective access protection' (sez. 5, principio del minimo privilegio implementato a livello aziendale). 'Privileged user accounts shall not be used for everyday work' = principio di non-promiscuità degli account privilegiati. DA POLICY MAN ES 13.1 Articolo 16 'Management of authorizations and passwords' punto (2): 'It shall be ensured that users only receive authorization appropriate to the tasks that they are required to carry out (minimum/adequate authorization allocation principle)'. Punto (4): 'Privileged user accounts shall not be used for everyday work'. Articolo 13 'Network security' punto (2): 'all network components shall be configured as restrictively as possible and safeguarded against unauthorized access. The principle of minimum authorization allocation shall be applied'. Principio di minimo privilegio implementato sia a livello applicativo (Art. 16) sia a livello rete (Art. 13). | E13: CEON-Security.png punti 8, 10 Final Certificate ISO/IEC 27001:2022 ISMS-4181-01 (standard) MAN ES_13.1_en_Instruction_1.pdf (Group Policy Information Security, applicable as of 01/03/2023), sez. 5 (standard) MAN ES_13.1_en_Instruction_1.pdf, Art. 13 punto (2), Art. 16 punti (2),(4) | F13: CONFORME | G13: Principio di minimo privilegio applicato a livello policy obbligatoria multi-area: principio di minima autorizzazione applicato sia su accessi applicativi (MAN ES 13.1 Art. 16 punto 2) sia su accessi rete (Art. 13 punto 2). Privileged accounts NOT for everyday work (Art. 16 punto 4). Asset-based access control + segmentation a livello prodotto (CEON-Security.png punto 8). | H13: Eventuale richiesta tecnica al fornitore: privilegi specifici di esecuzione Agent Shell/Core su ATU (root vs service account). | I13: BASSA
A14: 9 | B14: Controllo wireless | C14: SR 2.2 | D14: ATU = Hardened Device con wireless disabilitato (CEON-Security.png punto 1). Nessuna gestione wireless lato prodotto perché non presente. | E14: CEON-Security.png punto 1 | F14: CONFORME | G14: Wireless disabilitato by design. Nessuna gestione wireless necessaria. | H14: Verifica visiva on-site (vedi item 5). | I14: BASSA
A15: 10 | B15: Dispositivi USB | C15: SR 2.3 | D15: USB DISABILITATO sull'ATU come parte dell'hardening (CEON-Security.png punto 1: 'No interaction possible from outside (wireless, usb, ssh disabled)'). DNV certified come Hardened Device. Eccezione operativa: durante installazione PSA, viene usato un USB stick per backup database PMI (3. PSA Installation Guide v1.5.pdf, step 1: 'Create a database backup from PMI application and save it on a USB stick'). DA POLICY MAN ES 13.1: 'Removable data media shall be handled in accordance with the need to safeguard the data stored on them with regard to logical and physical aspects' (sez. 5). Policy aziendale formale sul controllo media rimovibili. DA POLICY MAN ES 13.1 Articolo 14 'To safeguard information and data media' punto (1): 'When exchanging information using portable data media, the data media shall be safeguarded appropriate to their specific need to safeguard'. Punto (2): 'Removable data media shall be handled in accordance with the need to safeguard the data stored on them with regard to logical and physical security'. Punto (3): 'On disposal of data media, it shall be ensured that confidential data is destroyed such that it cannot be restored'. Punto (4): 'Documented procedures for secure handling (storage and distribution) of information (on portable media) shall be established to prevent unauthorized inspection (access), misuse, or manipulation'. | E15: CEON-Security.png punto 1 3. PSA Installation Guide v1.5.pdf step 1 (standard) MAN ES_13.1_en_Instruction_1.pdf (Group Policy Information Security, applicable as of 01/03/2023), sez. 5 removable data media (standard) MAN ES_13.1_en_Instruction_1.pdf, Art. 14 punti (1)-(4) | F15: PARZIALMENTE CONFORME | G15: USB disabilitato by design su ATU in produzione. Eccezione: USB usato durante commissioning per backup PMI (operazione one-shot di setup, non operativa). Conferma nave per nave che USB sia effettivamente disabilitato post-commissioning. | H15: Verifica on-site: USB disabilitato su ATU GNV in produzione (BIOS, GPO, EDR). Procedure di commissioning con USB autorizzato/tracciato. | I15: MEDIA
A16: 11 | B16: Mobile code | C16: SR 2.4 | D16: ATU basato su Ubuntu Core minimal IoT OS o Windows; restrizioni esecuzione codice via OS sandboxing. CEON Web UI standard browser-based. DA WHISTIC NIST CSF DE.CM-5: 'Is unauthorized mobile code detected?' → YES. DA WHISTIC SIG LITE T.0.5: 'Documentation regarding the policies, standards, or guidelines regarding the use of mobile code in the environment for target systems' → 'Available upon request'. DA POLICY MAN ES 13.1: 'A virus protection policy shall be drawn up by the responsible operator(s), to prevent malicious software and mobile code, incorporate multiple testing of all items that may be affected by viruses. A virus scanner shall be installed on each work place computer.' Mobile code prevention è esplicitamente parte della policy MAN ES 13.1. | E16: ISMS ATU Release Management.pdf (Ubuntu Core snap packages) Architecture.png Cyber Security Questionnaires - Whistic - 2024.01.xlsx sez. DE.CM-5, T.0.5 (standard) MAN ES_13.1_en_Instruction_1.pdf (Group Policy Information Security, applicable as of 01/03/2023), sez. virus protection policy | F16: CONFORME | G16: Mobile code prevention coperta dalla virus protection policy MAN ES 13.1 + detection NIST DE.CM-5 confermata = controllo robusto. | H16: Verifica visiva durante demo CEON UI: lista plugin browser allowlist, JavaScript policy. | I16: BASSA
A17: 12 | B17: Blocco sessione | C17: SR 2.5 | D17: Sessione CEON Web UI presumibilmente con timeout di inattività (best practice SaaS). DA POLICY MAN ES 13.1 Articolo 19 'The use of information and communication facilities and devices' punto (1): 'Where technically possible, after a set period user inactivity shall automatically result in a block (e.g. screen, smartphone)'. Auto-lock per inattività è obbligatorio a livello policy MAN ES su tutti i dispositivi e applicazioni dove tecnicamente possibile. | E17: Architecture.png Security FAQ_v3.docx (standard) MAN ES_13.1_en_Instruction_1.pdf, Art. 19 punto (1) | F17: CONFORME | G17: Auto-lock per inattività garantito da policy MAN ES 13.1 Art. 19. Implementazione tecnica specifica del timeout (durata in minuti) non quantificata nel documento. | H17: Conferma operativa: durante demo CEON UI verificare il timeout effettivo (presumibilmente 15-30 min standard SaaS). | I17: BASSA
A18: 13 | B18: Log eventi sicurezza | C18: SR 2.8 | D18: MAN-CEON integra real-time monitoring, advanced anomaly detection, robust incident response (Security FAQ_v3.docx, sez. 'How does MAN-CEON help in detecting and responding to security incidents'). Continuous Risk Assessment con Intrusion detection/prevention, vulnerability management technology (CEON-Security.png punto 6). ISMS ISO 27001:2022 implementa logging e monitoring requirements (A.8.15-A.8.16). DA WHISTIC SIG LITE J.5: 'Is there a specific methodology to regularly review events on scoped systems or systems containing scoped data to uncover potential incidents?' → YES. DA WHISTIC J.5.1: 'Does regular security monitoring include alerts for malware infections and suspicious activity?' → YES. DA WHISTIC CAIQ LOG-04.1: 'Is access to audit logs restricted to authorized personnel, and are records maintained to provide unique access accountability?' → YES (CSP-Owned). DA WHISTIC CAIQ LOG-05.1: 'Are security audit logs monitored to detect activity outside of typical or expected patterns?' → YES (CSP-Owned). DA POLICY MAN ES 13.1: 'Monitoring and logging measures shall be assessed and set up accordingly. Any log data recorded shall be verified on a regular basis, automatically if possible' (sez. 5 punto monitoraggio). Verifica periodica dei log richiesta a livello policy aziendale. DA POLICY MAN ES 13.1 Articolo 18 'To safeguard system use' (interamente dedicato al logging): Punto (1): 'log data shall be created and stored'. Punto (2): 'security incidents and serious interruptions to MAN ES business processes to be tracked and evaluated via all participating networks, systems, and applications. The system times of all MAN ES systems and network components shall be synchronized'. Punto (5): 'the extent and content of required log information shall be determined on the basis of statutory and commercial requirements... As a minimum, information shall be available for appropriate tracking of security incidents'. Punto (6): 'Privileged activities forming part of the management of IT systems shall be logged and fully personalized'. | E18: Security FAQ_v3.docx (sez. Security incidents detection) CEON-Security.png punto 6 Final Certificate ISO/IEC 27001:2022 Cyber Security Questionnaires - Whistic - 2024.01.xlsx sez. J.5, J.5.1, LOG-04.1, LOG-05.1 (standard) MAN ES_13.1_en_Instruction_1.pdf (Group Policy Information Security, applicable as of 01/03/2023), sez. 5 (standard) MAN ES_13.1_en_Instruction_1.pdf, Art. 18 punti (1),(2),(5),(6) | F18: CONFORME | G18: Real-time monitoring + anomaly detection + IDS/IPS + ISMS ISO 27001 garantiscono coverage logging eventi sicurezza. Manca evidenza specifica dei tipi di evento loggati e accessibilità al cliente. | H18: Richiedere a MAN/Everllence: lista eventi loggati a livello CEON cloud + ATU, formato log, possibile esportazione verso SIEM cliente. | I18: MEDIA
A19: 14 | B19: Spazio storage log | C19: SR 2.9 | D19: Storage log lato cloud CEON gestito da AWS infrastructure (SOC 2 Type II compliant). High Availability data storage 99,99% (CEON-Security.png punto 7). DA WHISTIC SIG LITE G.0.8: 'Documentation on policy and procedures regarding log retention' → 'Available upon request'. DA WHISTIC K.11: 'Is there a data retention policy or process with a retention schedule for scoped data?' → YES. | E19: CEON-Security.png punto 7 System_and_Organization_Controls_(SOC)_2_Report.pdf Cyber Security Questionnaires - Whistic - 2024.01.xlsx sez. G.0.8, K.11 | F19: CONFORME | G19: Retention log e protezione storage formalmente coperti: log retention period fisso definito (MAN ES 13.1 Art. 18 punto 3), log safeguard contro accesso/manipolazione non autorizzata, deletion at end of retention. Storage cloud ad alta disponibilità (CEON-Security.png punto 7). | H19: Nessuna azione necessaria; periodi di retention specifici di prodotto possono essere richiesti al fornitore. | I19: BASSA
A20: 15 | B20: Failure del logging | C20: SR 2.10 | D20: Aspetto non dettagliato esplicitamente nei documenti. | E20: (non trattato nei documenti disponibili) | F20: PARZIALMENTE CONFORME | G20: Detection di anomalie di sistema coperta a livello policy: identification e evaluation timely di technical weaknesses (MAN ES 13.1 Art. 28 punto 1), automated detection di attack patterns/hacking attempts (Art. 28 punto 5). Comportamento specifico in caso di logging failure (alert visibile vs blocco operativo vs silente) non documentato esplicitamente. | H20: Eventuale chiarimento al fornitore: comportamento applicativo del sistema CEON in caso di failure logging (alert/blocco/silente). | I20: BASSA
A21: 16 | B21: Timestamp nei log | C21: SR 2.11 | D21: Time Sync via NTP confermato in architettura: ATU sincronizza tempo da CEON Backend NTP Service (Architecture.png). Time sync è uno dei flussi documentati: NTP UDP porta 123 verso server NTP MAN (91.189.94.4, 91.189.91.157, 35.156.77.222, 35.157.233.80, 35.156.61.78 — '2. Connectivity to CEON - Firewall requirements.pdf' Tabella 1 punto 3c). | E21: Architecture.png (NTP Service) 2. Connectivity to CEON - Firewall requirements.pdf Tabella 1 punto 3c | F21: CONFORME | G21: Time sync via NTP documentato e parte integrante dell'architettura. Timestamp nei log presumibilmente sincronizzati. | H21: Verificare configurazione NTP sui PC ATU GNV durante visita on-site. | I21: BASSA
A22: FR3 — Integrità del sistema
A23: 17 | B23: Integrità comunicazioni | C23: SR 3.1 | D23: Comunicazioni protette tramite TLS (latest version) per tutti i flussi (CEON-Security.png punto 5: 'Outbound only: Our outbound protocols are using latest TLS version'). Security FAQ_v3.docx conferma 'advanced Transport Layer Security (TLS) protocols for encryption' applicato a tutti i dati in transit (ATU-cloud + browser-frontend + frontend-backend). Encryption-in-transit con AES standard. | E23: CEON-Security.png punto 5 Security FAQ_v3.docx (sez. Data protection in transit) Everllence_Standard_ATU-mGuard_Network_REV02.pdf | F23: CONFORME | G23: Integrità comunicazioni garantita da TLS latest version + AES encryption. Architettura outbound-only verso CEON cloud, no inbound a edge device. Nessun gap residuo significativo. | H23: Richiedere a MAN/Everllence: versione TLS minima accettata, suite cipher disabilitate, gestione certificati TLS (validità, rotation). | I23: BASSA
A24: 18 | B24: Protezione malware | C24: SR 3.2 | D24: ATU è Hardened Device con sistema operativo dedicato (Ubuntu Core minimal IoT OS o Windows). Continuous Risk Assessment con vulnerability management e mitigation (CEON-Security.png punto 6). Snap packages Ubuntu Core forniscono applicazioni confinate. Pen test annuale (Pentest2025redacted.pdf) include retesting di vulnerabilità precedenti. DA POLICY MAN ES 13.1: 'A virus protection policy shall be drawn up... A virus scanner shall be installed on each work place computer. Updates of the antivirus software/malware code shall be initiated automatically on system start, shall download updates automatically where possible, and shall be prevented from being shut down by users.' Policy aziendale di protezione antimalware molto dettagliata. DA POLICY MAN ES 13.1 Articolo 26 'To prevent malicious software and mobile code' (interamente dedicato a antimalware): Punto (3): 'All data traffic from or within public networks shall be automatically checked for viruses by a central virus protection system. Virus protection shall be able to check compressed or encrypted files where technically possible'. Punto (4): 'A process shall be developed for correctly dealing with virus-infected content. Active content such as in downloads or websites from public networks shall have its system conformity verified by central systems before being transferred'. Punto (5): 'Only those services and functionalities shall be made available on the systems (client and server) that are required for the intended purpose'. Punto (6): 'Security software and settings shall be configured such that no modifications are possible by the user and that the function cannot be shut down'. Punto (7): 'IT systems in production environments (such as industrial PCs) shall be safeguarded against malicious software insofar as these systems provide access to the Internet, or mobile data media are used. If this is not possible, these systems shall by isolated as appropriate by means of network separation and deactivation of ports'. | E24: CEON-Security.png punti 1, 6 ISMS ATU Release Management.pdf Pentest2025redacted.pdf (Recurity Labs ottobre 2025) (standard) MAN ES_13.1_en_Instruction_1.pdf (Group Policy Information Security, applicable as of 01/03/2023), sez. virus protection policy (standard) MAN ES_13.1_en_Instruction_1.pdf, Art. 26 punti (3)-(7) | F24: CONFORME | G24: Hardening + Ubuntu Core confinato + vulnerability management + pentest annuale = posture malware-resistant solida. Manca menzione esplicita di antivirus/EDR su ATU Windows-based (variante). | H24: Richiedere a MAN/Everllence: presenza antivirus/EDR su ATU variant Windows, integrazione possibile con Cortex XDR (richiesto da GNV). | I24: MEDIA
A25: 19 | B25: Test sicurezza | C25: SR 3.3 | D25: Penetration test continuo dichiarato (CEON-Security.png punto 11: 'Continous Pentest: Dedicated cyber security teams perform regular black- and white hat assessments across the complete Everllence CEON architecture'). Pentest 2025 condotto da Recurity Labs GmbH (Project No. 507.2503, ottobre 2025, 110 pagine) con scope completo: PrimeServ Assist Mobile App, Web Apps, AWS Infrastructure. Test plan include: Documentation Integrity, Migration Remnant, Attack Model, Compare Preprod/Prod, IAC Integrity, Configuration Review. SECONDO PENTEST DOCUMENTATO (RedactedPentest.pdf): 'API Services Retest', Project No. 241.2305, Recurity Labs GmbH, dicembre 2023 (drafted 21/12/2023, finalized 22/12/2023), 45 pagine totali. 12 retested findings ai capitoli 3.1-3.12. Combinato con il pentest 2025 (Mya CEON Security Assessment & Retest, Project 507.2503, ottobre 2025) conferma cadenza pentest ~ogni 2 anni con retest dei findings precedenti. DA WHISTIC SIG LITE T.1: 'Is there a centrally managed Vulnerability Management Program and associated Policy that has been approved by management, communicated to appropriate constituents and has an owner to maintain it?' → YES. DA WHISTIC NIST PR.IP-12: 'Is a vulnerability management plan developed and implemented?' → YES. DA POLICY MAN ES 13.1 Articolo 31 'Verification of Information Security' punto (4): 'Technical Information Security must be assessed by measures such as regular penetration tests or security audits'. Punto (5): 'The organizational Information Security must be checked by regular process audits such as self-assessments, on-site assessments, management assessments or assessments by external partners'. Articolo 28 punto (5): 'In order to identify and tackle attacks and network hacking attempts at MAN ES in a timely manner, systems shall be used to automatically detect and/or prevent attack patterns and hacking attempts'. Pentest 2023 + 2025 da Recurity Labs sono evidenze concrete di applicazione di Art. 31 punto (4). | E25: CEON-Security.png punto 11 Pentest2025redacted.pdf (Recurity Labs, Project No. 507.2503, ottobre 2025, 110 pagine) RedactedPentest.pdf (API Services Retest 2023) Cyber Security Questionnaires - Whistic - 2024.01.xlsx sez. T.1, PR.IP-12 (standard) MAN ES_13.1_en_Instruction_1.pdf, Art. 28 punto (5), Art. 31 punti (4),(5) | F25: CONFORME | G25: Pentest annuale documentato con vendor cyber-security qualificato (Recurity Labs). Findings redatti nel documento condiviso (per confidenzialità) ma esistenza test confermata. Test plan completo e strutturato. | H25: Richiedere a MAN/Everllence: estratto findings principali del pentest 2025 (anche solo executive summary o lista categorie di vulnerabilità trovate), conferma chiusura findings critici/high. | I25: BASSA
A26: 20 | B26: Stato sicuro (fail-safe) | C26: SR 3.4 | D26: ATU è dispositivo di data acquisition (signal data acquisition Linux/Windows-based — Architecture.png), non controlla attuatori. Se ATU va in failure, l'engine continua il funzionamento normale (l'EMS computer è separato dal controllo motore principale; PSA Installation Guide step 'Important: the following steps must be done while the main engine is OFF' indica che il sistema PSA non è critico per il funzionamento del motore). | E26: Architecture.png 3. PSA Installation Guide v1.5.pdf | F26: CONFORME | G26: Sistema PSA è advisory/monitoring, non controlla la propulsione. In caso di failure ATU, motore continua a operare normalmente. | H26: Confermare con MAN che PSA è puramente advisory e non integrato nel controllo safety-critical motore. | I26: BASSA
A27: FR4 — Confidenzialità dei dati
A28: 21 | B28: Protezione dati | C28: SR 4.1 | D28: Encryption-at-rest tramite AES symmetric encryption per dati sensibili (Security FAQ_v3.docx, sez. 'How does MAN-CEON encrypt sensitive data'). Storage AWS in EU/Frankfurt (EU-Central 1) per data residency GDPR-compliant. Cifratura dati 'in transit and at rest using the de facto Advanced Encryption Standard (AES) symmetric encryption algorithm'. Dati immagazzinati in Germania (CEON-Security.png punto 7). | E28: Security FAQ_v3.docx (sez. Data encryption) CEON-Security.png punto 7 Final Certificate ISO/IEC 27001:2022 ISMS-4181-01 | F28: CONFORME | G28: Encryption at rest + in transit + AES + data residency GDPR-compliant + ISO 27001. Coverage E27 SR 4.1 solida. | H28: Nessuna azione necessaria; eventuali dettagli tecnici (AES-256? AES-128? GCM?) richiedibili a MAN. | I28: BASSA
A29: 22 | B29: Crittografia | C29: SR 4.3 | D29: AES symmetric encryption per dati at rest e in transit (Security FAQ_v3.docx). TLS latest version per tutti i flussi (CEON-Security.png punto 5). AWS KMS per key management con envelope encryption (Security FAQ_v3.docx). VPN IPSec per remote access (Everllence_Standard_ATU-mGuard_Network_REV02.pdf). | E29: Security FAQ_v3.docx CEON-Security.png punto 5 Everllence_Standard_ATU-mGuard_Network_REV02.pdf | F29: CONFORME | G29: Crittografia robusta multi-layer: TLS latest, AES, AWS KMS, IPSec. Algoritmi standard di settore. | H29: Richiedere a MAN/Everllence: dettagli specifici (TLS minimum version 1.2 o 1.3, suite cipher accettate, AES-256 confermato). | I29: BASSA
A30: FR6 — Risposta agli eventi
A31: 23 | B31: Accessibilità log audit | C31: SR 6.1 | D31: Real-time monitoring + anomaly detection + incident response su CEON cloud (Security FAQ_v3.docx). ISMS ISO 27001 implementa controlli A.8.15-A.8.16 su logging e monitoring. Log eventi sicurezza disponibili lato CEON; accessibilità ai log per il cliente non documentata esplicitamente. DA POLICY MAN ES 13.1 Articolo 18 'To safeguard system use' punto (3): 'Log data and log files shall be retained for a fixed period in case they may be useful in future investigations. Logs shall be safeguarded against unauthorized access and manipulation and shall be deleted upon expiry of the fixed retention period'. Punto (7): 'Log files shall be evaluated such that events critical to security are identified in good time. It shall be ensured that personnel are appropriately trained for the evaluation of log information'. Punto (6): 'Privileged activities forming part of the management of IT systems shall be logged and fully personalized. The conformity of logging procedures shall be tested by an independent body against defined procedures on a regular basis'. Punto (5): 'As a result of a risk analysis the extent and content of required log information shall be determined on the basis of statutory and commercial requirements for the identified systems. As a minimum, information shall be available for appropriate tracking of security incidents'. | E31: Security FAQ_v3.docx Final Certificate ISO/IEC 27001:2022 (standard) MAN ES_13.1_en_Instruction_1.pdf, Art. 18 punti (3),(5),(6),(7) | F31: PARZIALMENTE CONFORME | G31: Logging policy MAN ES 13.1 Art. 18 garantisce: retention periodica, protezione log da accessi non autorizzati e manipolazione, evaluation periodica per detection eventi critici, audit indipendente delle procedure di logging, logging fully personalized degli accessi privilegiati. Manca dettaglio specifico sull'accessibilità lato cliente CEON (export verso SIEM). | H31: Richiedere a MAN: meccanismo di accesso log audit lato cliente (UI CEON, API, syslog forwarding); formato esportabile (JSON, CEF, syslog) per integrazione SIEM cliente Cortex XDR. | I31: MEDIA
A32: FR7 — Disponibilità delle risorse
A33: 24 | B33: Protezione DoS | C33: SR 7.1 | D33: Architettura cloud AWS-hosted con high availability 99,99% (CEON-Security.png punto 7). AWS infrastructure include protezione DDoS standard (AWS Shield). Continuous Risk Assessment con IDS/IPS (CEON-Security.png punto 6). | E33: CEON-Security.png punti 6, 7 System_and_Organization_Controls_(SOC)_2_Report.pdf | F33: CONFORME | G33: Protezione DoS lato cloud garantita da AWS Shield (standard). Lato ATU edge: outbound-only protocol limita esposizione DoS inbound. | H33: Richiedere a MAN: AWS Shield Standard o Advanced? Protezioni rate limiting su API CEON? | I33: BASSA
A34: 25 | B34: Gestione risorse | C34: SR 7.2 | D34: ATU CEON con Edge Processing per data buffering e aggregation per ridurre bandwidth (CEON-Security.png punto 2). Hardware B&R APC2200 industrial PC dimensionato per workload data acquisition. | E34: CEON-Security.png punto 2 B&R_APC2200_UserManual_ENG_V2.02.pdf | F34: CONFORME | G34: Gestione risorse documentata a livello architetturale. Buffering edge previene overflow rete. | H34: Verifica monitoring CPU/RAM/disco ATU su navi GNV in produzione, alert configurati. | I34: BASSA
A35: 26 | B35: Backup | C35: SR 7.3 | D35: High Availability, Secure Data Storage con data backup integrato (CEON-Security.png punto 7: '99,99% infrastructure availability, data backup, platform provider ISO27001 and CIS certified; data securely stored within Germany'). Backup PMI database via USB stick come parte della procedura di installazione (3. PSA Installation Guide v1.5.pdf step 1). DA POLICY MAN ES 13.1: 'A concept for data backup and recovery shall be defined for each system. Data backup and recovery this general concept shall also appoint responsibilities.' Backup obbligatorio a livello policy MAN ES per ogni sistema, con responsabilità definite. DA POLICY MAN ES 13.1 Articolo 25 'Data backup and recovery' punto (1): 'A concept for data backup and recovery shall be defined for each system. This general concept shall also appoint responsibilities'. Punto (4): 'The data security concept shall undergo a detailed test at least once a year. The result of the test shall be documented and stored as proof'. Punto (5): 'The same access restrictions shall apply to the storage location of data backups as for systems on which original data are stored'. Punto (6): 'Data backup media shall be catalogued and have their completeness and readability tested on a regular basis'. Punto (7): 'The ability to restore data critical to business shall be tested at least once a year. All tests carried out shall be documented'. | E35: CEON-Security.png punto 7 3. PSA Installation Guide v1.5.pdf step 1 (standard) MAN ES_13.1_en_Instruction_1.pdf (Group Policy Information Security, applicable as of 01/03/2023), sez. 5 backup and recovery (standard) MAN ES_13.1_en_Instruction_1.pdf, Art. 25 punti (1),(4),(5),(6),(7) | F35: CONFORME | G35: Backup cloud-side automatico parte del servizio CEON (AWS-managed). Backup database PMI durante commissioning documentato. | H35: Richiedere a MAN: frequenza backup CEON cloud, retention, possibilità di restore on-demand su richiesta cliente. | I35: BASSA
A36: 27 | B36: Ripristino | C36: SR 7.4 | D36: Backup cloud-side disponibile (item 26). Procedura di ripristino EMS computer documentata in PSA Installation Guide (step 4: ripristino backup PMI da USB stick durante setup nuovo EMS). Ubuntu Core su ATU permette factory reset e ri-registrazione automatica (ISMS ATU Release Management.pdf: 'Newly connected ATUs automatically register and update to the current release'). DA WHISTIC SIG LITE K.1: 'Has the organization established a Business Resilience Policy, designated an owner to maintain and review it, and communicated it?' → YES. DA WHISTIC K.2: 'Is there a formal, documented information technology disaster recovery exercise and testing program in place?' → YES. DA WHISTIC K.5: 'Is scoped data backed up and stored offsite?' → YES (note: '100% AWS'). DA WHISTIC K.7: 'Have formal procedures for business continuity been developed and documented?' → YES. DA WHISTIC NIST RC.RP-1: 'Is the recovery plan executed during or after a cybersecurity incident?' → YES. DA WHISTIC NIST RC.IM-1: 'Do recovery plans incorporate lessons learned?' → YES. DA WHISTIC NIST PR.IP-10: 'Are response and recovery plans tested?' → YES. Documenti dettagliati 'Backup and recovery plan procedures' (J.0.10) e 'Crisis management and business continuity and disaster recovery plans' (K.0.4) disponibili su richiesta via Whistic. DA POLICY MAN ES 13.1: documentation per recovery di sistemi critici prevista per garantire continuity ('such that in the event of a personnel deficiency or system function error, normal operation can be resumed as quickly as possible'). Da AWS SOC 2 Type II Report: documentazione operativa AWS BCP/DRP coperta per la piattaforma cloud sottostante che ospita CEON. DA POLICY MAN ES 13.1 Articolo 5 'Business and IT service continuity management': 'All MAN ES Group companies shall establish an integrated business and IT service continuity management process. Emergency measures appropriate to the determined risk shall be realized, regularly tested, and adjusted on the basis of a business impact analysis'. Articolo 20 punto (3): 'It shall be ensured that documentation necessary for operation and recovery of critical assets is available in case of business interruptions (e.g. as printout, encrypted on CD/DVD/USB drives)'. Articolo 25 punto (7): test annuale documentato della capacità di restore. | E36: 3. PSA Installation Guide v1.5.pdf step 4 ISMS ATU Release Management.pdf Cyber Security Questionnaires - Whistic - 2024.01.xlsx sez. K.1, K.2, K.5, K.7, RC.RP-1, RC.IM-1, PR.IP-10 (standard) MAN ES_13.1_en_Instruction_1.pdf (Group Policy Information Security, applicable as of 01/03/2023), sez. operational procedures System_and_Organization_Controls_(SOC)_2_Report.pdf (AWS underlying infrastructure) (standard) MAN ES_13.1_en_Instruction_1.pdf, Art. 5 + Art. 20 punto (3) + Art. 25 punto (7) | F36: CONFORME | G36: Procedura di ripristino documentata sia per EMS computer (locale) sia per ATU (auto-recovery via re-registrazione cloud). | H36: Verificare con MAN: tempi RTO/RPO documentati, runbook formale di disaster recovery. | I36: MEDIA
A37: 28 | B37: Alimentazione emergenza | C37: SR 7.5 | D37: PSA Installation Guide include Appendix 1 'ECR UPS power supply' (3. PSA Installation Guide v1.5.pdf, p. 15) con dettaglio alimentazione UPS in Engine Control Room. Alimentazione mGuard + Managed Switch + EMS = 24 VDC (PSA Installation Guide step 2). UPS deve essere fornito dal cliente per protezione apparati ECR. | E37: 3. PSA Installation Guide v1.5.pdf Appendix 1 (ECR UPS power supply) | F37: PARZIALMENTE CONFORME | G37: MAN documenta la necessità di UPS in ECR ma la fornitura UPS è responsabilità del cliente (GNV). Da verificare nave per nave su GNV: presenza UPS, capacità, autonomia. | H37: Verifica nave per nave: UPS presente in ECR per alimentare mGuard + Managed Switch + EMS, autonomia adeguata, manutenzione periodica. | I37: MEDIA
A38: 29 | B38: Configurazione rete | C38: SR 7.6 | D38: Architettura rete documentata in dettaglio: Ship Network → mGuard WAN → mGuard LAN → MAN Managed Switch (16-port) → EMS Computer (port 2) + MOP B (port 3) + PMI-DAU (port 4) + ERCS Tier III (port 5) + AMS (port 6) (3. PSA Installation Guide v1.5.pdf step 2). VLAN 1 sul nostro switch nave (Network.txt: VIR-DIS16-DK2-MVZ5 interface 3/1/21, MAC a8:74:1d:f2:2a:77). Connessione mGuard WAN → VSAT switch con Internet attivo. Cavo CAT 6/STP minimo. IP statico o DHCP. Firewall regole esposte in '2. Connectivity to CEON - Firewall requirements.pdf' Tabella 1: porte 443 TCP, 123 UDP, 500 UDP, 4500 UDP verso IP CEON specifici (35.156.77.222, 35.157.233.80, 35.156.61.78, 149.247.176.129). | E38: 3. PSA Installation Guide v1.5.pdf step 2 Network.txt 2. Connectivity to CEON - Firewall requirements.pdf Tabella 1 Everllence_Standard_ATU-mGuard_Network_REV02.pdf | F38: CONFORME | G38: Configurazione rete dettagliata e documentata. Firewall ports e IP destinazione esplicitati. Architettura segregata con mGuard come perimetro. | H38: Verifica nave per nave: rispetto delle regole firewall come da Tabella 1, segregazione VLAN MAN da VLAN GNV. | I38: BASSA
A39: 30 | B39: Hardening | C39: SR 7.7 | D39: ATU è Hardened Device DNV certified (CEON-Security.png punto 1). Wireless/USB/SSH disabilitati. Ubuntu Core minimal IoT OS con snap packages confined (ISMS ATU Release Management.pdf). Patch automatiche tramite Snap Store per OS updates. ISMS ISO 27001:2022 implementa hardening guidelines come controlli A.8.9 (Configuration management). DA POLICY MAN ES 13.1: 'A secure configuration shall be defined as part of system hardening for business critical systems. Those shall be used as basis for a secure installation' (sez. 5 punto secure configuration). Hardening è parte formale della policy aziendale MAN ES per sistemi business-critical (categoria che include i prodotti CEON ATU). DA POLICY MAN ES 13.1 Articolo 24 'To procure systems on the basis of defined criteria' punto (1): 'It shall be ensured that all new IT systems and services fulfil the requirements of the MAN ES Group with regard to Information Security'. Punto (2): 'A secure configuration shall be defined as part of system hardening for business critical systems. Those shall be used as basis for a secure installation and serve as a checklist for monitoring'. Hardening obbligatorio + checklist di monitoraggio per sistemi business-critical (categoria che include i prodotti CEON ATU). | E39: CEON-Security.png punto 1 ISMS ATU Release Management.pdf Final Certificate ISO/IEC 27001:2022 (standard) MAN ES_13.1_en_Instruction_1.pdf (Group Policy Information Security, applicable as of 01/03/2023), sez. 5 secure configuration (standard) MAN ES_13.1_en_Instruction_1.pdf, Art. 24 punti (1),(2) | F39: CONFORME | G39: Hardening documentato a livello prodotto + DNV certified + ISMS ISO 27001. Coverage solida. | H39: Richiedere a MAN: documento hardening guidelines formale (CIS Benchmark? STIG? proprietary checklist?), eventuali eccezioni documentate. | I39: BASSA
A40: Sez. 4.2 — Additional security capabilities (reti untrusted)
...

Sheet Riepilogo
A1: Riepilogo — Analisi E27 MAN Stability / Loading Computer / Fleet Intelligence
A3: CONTEGGIO AUTOMATICO STATO (aggiornamento dinamico dal foglio Analisi)
A4: # | B4: Stato | C4: Conteggio | D4: Totale | E4: Percentuale
A5: 1 | B5: CONFORME | C5: =COUNTIF('Analisi E27 — MAN'!$F$5:$F$66,"CONFORME") -> 38 | D5: =COUNTIF('Analisi E27 — MAN'!$F$5:$F$66,"CONFORME")+COUNTIF('Analisi E27 — MAN'!$F$5:$F$66,"PARZIALMENTE CONFORME")+COUNTIF('Analisi E27 — MAN'!$F$5:$F$66,"NON CONFORME")+COUNTIF('Analisi E27 — MAN'!$F$5:$F$66,"DA VERIFICARE")+COUNTIF('Analisi E27 — MAN'!$F$5:$F$66,"N/A") -> 51 | E5: =IF(D5=0,"",C5/D5) -> 0.74509804
A6: 2 | B6: PARZIALMENTE CONFORME | C6: =COUNTIF('Analisi E27 — MAN'!$F$5:$F$66,"PARZIALMENTE CONFORME") -> 13 | D6: =COUNTIF('Analisi E27 — MAN'!$F$5:$F$66,"CONFORME")+COUNTIF('Analisi E27 — MAN'!$F$5:$F$66,"PARZIALMENTE CONFORME")+COUNTIF('Analisi E27 — MAN'!$F$5:$F$66,"NON CONFORME")+COUNTIF('Analisi E27 — MAN'!$F$5:$F$66,"DA VERIFICARE")+COUNTIF('Analisi E27 — MAN'!$F$5:$F$66,"N/A") -> 51 | E6: =IF(D6=0,"",C6/D6) -> 0.25490196
A7: 3 | B7: NON CONFORME | C7: =COUNTIF('Analisi E27 — MAN'!$F$5:$F$66,"NON CONFORME") -> 0 | D7: =COUNTIF('Analisi E27 — MAN'!$F$5:$F$66,"CONFORME")+COUNTIF('Analisi E27 — MAN'!$F$5:$F$66,"PARZIALMENTE CONFORME")+COUNTIF('Analisi E27 — MAN'!$F$5:$F$66,"NON CONFORME")+COUNTIF('Analisi E27 — MAN'!$F$5:$F$66,"DA VERIFICARE")+COUNTIF('Analisi E27 — MAN'!$F$5:$F$66,"N/A") -> 51 | E7: =IF(D7=0,"",C7/D7) -> 0
A8: 4 | B8: DA VERIFICARE | C8: =COUNTIF('Analisi E27 — MAN'!$F$5:$F$66,"DA VERIFICARE") -> 0 | D8: =COUNTIF('Analisi E27 — MAN'!$F$5:$F$66,"CONFORME")+COUNTIF('Analisi E27 — MAN'!$F$5:$F$66,"PARZIALMENTE CONFORME")+COUNTIF('Analisi E27 — MAN'!$F$5:$F$66,"NON CONFORME")+COUNTIF('Analisi E27 — MAN'!$F$5:$F$66,"DA VERIFICARE")+COUNTIF('Analisi E27 — MAN'!$F$5:$F$66,"N/A") -> 51 | E8: =IF(D8=0,"",C8/D8) -> 0
A9: 5 | B9: N/A | C9: =COUNTIF('Analisi E27 — MAN'!$F$5:$F$66,"N/A") -> 0 | D9: =COUNTIF('Analisi E27 — MAN'!$F$5:$F$66,"CONFORME")+COUNTIF('Analisi E27 — MAN'!$F$5:$F$66,"PARZIALMENTE CONFORME")+COUNTIF('Analisi E27 — MAN'!$F$5:$F$66,"NON CONFORME")+COUNTIF('Analisi E27 — MAN'!$F$5:$F$66,"DA VERIFICARE")+COUNTIF('Analisi E27 — MAN'!$F$5:$F$66,"N/A") -> 51 | E9: =IF(D9=0,"",C9/D9) -> 0
B10: TOTALE | C10: =SUM(C5:C9) -> 51 | D10: =COUNTIF('Analisi E27 — MAN'!$F$5:$F$66,"CONFORME")+COUNTIF('Analisi E27 — MAN'!$F$5:$F$66,"PARZIALMENTE CONFORME")+COUNTIF('Analisi E27 — MAN'!$F$5:$F$66,"NON CONFORME")+COUNTIF('Analisi E27 — MAN'!$F$5:$F$66,"DA VERIFICARE")+COUNTIF('Analisi E27 — MAN'!$F$5:$F$66,"N/A") -> 51
A12: DETTAGLIO PER ITEM (stato e priorità aggiornati automaticamente dal foglio Analisi)
A13: Item | B13: Controllo | C13: Stato | D13: Priorità | E13: Cosa fare
A14: Sezione 4.1 — System Requirements (30 controlli base)
A15: 1 | B15: ='Analisi E27 — MAN'!B5 -> Identificazione utente | C15: ='Analisi E27 — MAN'!F5 -> CONFORME | D15: ='Analisi E27 — MAN'!I5 -> BASSA | E15: ='Analisi E27 — MAN'!H5 -> Verificare on-site sui PC ATU GNV: utenti locali presenti, integrazione Active Directory (se applicabile).
A16: 2 | B16: ='Analisi E27 — MAN'!B6 -> Gestione account | C16: ='Analisi E27 — MAN'!F6 -> CONFORME | D16: ='Analisi E27 — MAN'!I6 -> BASSA | E16: ='Analisi E27 — MAN'!H6 -> Nessuna azione necessaria; eventuale verifica di una sample report di account review può essere richiesta al fornitore (Whistic H.0.5).
A17: 3 | B17: ='Analisi E27 — MAN'!B7 -> Gestione ruoli | C17: ='Analisi E27 — MAN'!F7 -> CONFORME | D17: ='Analisi E27 — MAN'!I7 -> BASSA | E17: ='Analisi E27 — MAN'!H7 -> Nessuna azione strettamente necessaria; matrice ruoli/permessi tecnica specifica del prodotto CEON può essere richiesta in fase di operations setup.
A18: 4 | B18: ='Analisi E27 — MAN'!B8 -> Gestione credenziali | C18: ='Analisi E27 — MAN'!F8 -> PARZIALMENTE CONFORME | D18: ='Analisi E27 — MAN'!I8 -> MEDIA | E18: ='Analisi E27 — MAN'!H8 -> Richiedere a MAN/Everllence: policy password formale (min length, complexity, history, expiry), procedure reset password sicure, esistenza forced password change al primo login.
A19: 5 | B19: ='Analisi E27 — MAN'!B9 -> Accesso wireless | C19: ='Analisi E27 — MAN'!F9 -> CONFORME | D19: ='Analisi E27 — MAN'!I9 -> BASSA | E19: ='Analisi E27 — MAN'!H9 -> Verifica visiva on-site sui PC ATU GNV: assenza adapter wireless attivi, conferma BIOS lock di interfacce wireless.
A20: 6 | B20: ='Analisi E27 — MAN'!B10 -> Robustezza password | C20: ='Analisi E27 — MAN'!F10 -> PARZIALMENTE CONFORME | D20: ='Analisi E27 — MAN'!I10 -> MEDIA | E20: ='Analisi E27 — MAN'!H10 -> Richiedere a MAN tramite Whistic platform il documento 'Corporate password policy and procedures' (riferimento Whistic H.0.2).
A21: 7 | B21: ='Analisi E27 — MAN'!B11 -> Mascheratura password | C21: ='Analisi E27 — MAN'!F11 -> PARZIALMENTE CONFORME | D21: ='Analisi E27 — MAN'!I11 -> BASSA | E21: ='Analisi E27 — MAN'!H11 -> Verifica visiva durante demo CEON cloud UI: campo password mascherato, no echo plaintext.
A22: 8 | B22: ='Analisi E27 — MAN'!B13 -> Minimo privilegio | C22: ='Analisi E27 — MAN'!F13 -> CONFORME | D22: ='Analisi E27 — MAN'!I13 -> BASSA | E22: ='Analisi E27 — MAN'!H13 -> Eventuale richiesta tecnica al fornitore: privilegi specifici di esecuzione Agent Shell/Core su ATU (root vs service account).
A23: 9 | B23: ='Analisi E27 — MAN'!B14 -> Controllo wireless | C23: ='Analisi E27 — MAN'!F14 -> CONFORME | D23: ='Analisi E27 — MAN'!I14 -> BASSA | E23: ='Analisi E27 — MAN'!H14 -> Verifica visiva on-site (vedi item 5).
A24: 10 | B24: ='Analisi E27 — MAN'!B15 -> Dispositivi USB | C24: ='Analisi E27 — MAN'!F15 -> PARZIALMENTE CONFORME | D24: ='Analisi E27 — MAN'!I15 -> MEDIA | E24: ='Analisi E27 — MAN'!H15 -> Verifica on-site: USB disabilitato su ATU GNV in produzione (BIOS, GPO, EDR). Procedure di commissioning con USB autorizzato/tracciato.
A25: 11 | B25: ='Analisi E27 — MAN'!B16 -> Mobile code | C25: ='Analisi E27 — MAN'!F16 -> CONFORME | D25: ='Analisi E27 — MAN'!I16 -> BASSA | E25: ='Analisi E27 — MAN'!H16 -> Verifica visiva durante demo CEON UI: lista plugin browser allowlist, JavaScript policy.
A26: 12 | B26: ='Analisi E27 — MAN'!B17 -> Blocco sessione | C26: ='Analisi E27 — MAN'!F17 -> CONFORME | D26: ='Analisi E27 — MAN'!I17 -> BASSA | E26: ='Analisi E27 — MAN'!H17 -> Conferma operativa: durante demo CEON UI verificare il timeout effettivo (presumibilmente 15-30 min standard SaaS).
A27: 13 | B27: ='Analisi E27 — MAN'!B18 -> Log eventi sicurezza | C27: ='Analisi E27 — MAN'!F18 -> CONFORME | D27: ='Analisi E27 — MAN'!I18 -> MEDIA | E27: ='Analisi E27 — MAN'!H18 -> Richiedere a MAN/Everllence: lista eventi loggati a livello CEON cloud + ATU, formato log, possibile esportazione verso SIEM cliente.
A28: 14 | B28: ='Analisi E27 — MAN'!B19 -> Spazio storage log | C28: ='Analisi E27 — MAN'!F19 -> CONFORME | D28: ='Analisi E27 — MAN'!I19 -> BASSA | E28: ='Analisi E27 — MAN'!H19 -> Nessuna azione necessaria; periodi di retention specifici di prodotto possono essere richiesti al fornitore.
A29: 15 | B29: ='Analisi E27 — MAN'!B20 -> Failure del logging | C29: ='Analisi E27 — MAN'!F20 -> PARZIALMENTE CONFORME | D29: ='Analisi E27 — MAN'!I20 -> BASSA | E29: ='Analisi E27 — MAN'!H20 -> Eventuale chiarimento al fornitore: comportamento applicativo del sistema CEON in caso di failure logging (alert/blocco/silente).
A30: 16 | B30: ='Analisi E27 — MAN'!B21 -> Timestamp nei log | C30: ='Analisi E27 — MAN'!F21 -> CONFORME | D30: ='Analisi E27 — MAN'!I21 -> BASSA | E30: ='Analisi E27 — MAN'!H21 -> Verificare configurazione NTP sui PC ATU GNV durante visita on-site.
A31: 17 | B31: ='Analisi E27 — MAN'!B23 -> Integrità comunicazioni | C31: ='Analisi E27 — MAN'!F23 -> CONFORME | D31: ='Analisi E27 — MAN'!I23 -> BASSA | E31: ='Analisi E27 — MAN'!H23 -> Richiedere a MAN/Everllence: versione TLS minima accettata, suite cipher disabilitate, gestione certificati TLS (validità, rotation).
A32: 18 | B32: ='Analisi E27 — MAN'!B24 -> Protezione malware | C32: ='Analisi E27 — MAN'!F24 -> CONFORME | D32: ='Analisi E27 — MAN'!I24 -> MEDIA | E32: ='Analisi E27 — MAN'!H24 -> Richiedere a MAN/Everllence: presenza antivirus/EDR su ATU variant Windows, integrazione possibile con Cortex XDR (richiesto da GNV).
A33: 19 | B33: ='Analisi E27 — MAN'!B25 -> Test sicurezza | C33: ='Analisi E27 — MAN'!F25 -> CONFORME | D33: ='Analisi E27 — MAN'!I25 -> BASSA | E33: ='Analisi E27 — MAN'!H25 -> Richiedere a MAN/Everllence: estratto findings principali del pentest 2025 (anche solo executive summary o lista categorie di vulnerabilità trovate), conferma chiusura findings critici/high.
A34: 20 | B34: ='Analisi E27 — MAN'!B26 -> Stato sicuro (fail-safe) | C34: ='Analisi E27 — MAN'!F26 -> CONFORME | D34: ='Analisi E27 — MAN'!I26 -> BASSA | E34: ='Analisi E27 — MAN'!H26 -> Confermare con MAN che PSA è puramente advisory e non integrato nel controllo safety-critical motore.
A35: 21 | B35: ='Analisi E27 — MAN'!B28 -> Protezione dati | C35: ='Analisi E27 — MAN'!F28 -> CONFORME | D35: ='Analisi E27 — MAN'!I28 -> BASSA | E35: ='Analisi E27 — MAN'!H28 -> Nessuna azione necessaria; eventuali dettagli tecnici (AES-256? AES-128? GCM?) richiedibili a MAN.
A36: 22 | B36: ='Analisi E27 — MAN'!B29 -> Crittografia | C36: ='Analisi E27 — MAN'!F29 -> CONFORME | D36: ='Analisi E27 — MAN'!I29 -> BASSA | E36: ='Analisi E27 — MAN'!H29 -> Richiedere a MAN/Everllence: dettagli specifici (TLS minimum version 1.2 o 1.3, suite cipher accettate, AES-256 confermato).
A37: 23 | B37: ='Analisi E27 — MAN'!B31 -> Accessibilità log audit | C37: ='Analisi E27 — MAN'!F31 -> PARZIALMENTE CONFORME | D37: ='Analisi E27 — MAN'!I31 -> MEDIA | E37: ='Analisi E27 — MAN'!H31 -> Richiedere a MAN: meccanismo di accesso log audit lato cliente (UI CEON, API, syslog forwarding); formato esportabile (JSON, CEF, syslog) per integrazione SIEM cliente Cortex XDR.
A38: 24 | B38: ='Analisi E27 — MAN'!B33 -> Protezione DoS | C38: ='Analisi E27 — MAN'!F33 -> CONFORME | D38: ='Analisi E27 — MAN'!I33 -> BASSA | E38: ='Analisi E27 — MAN'!H33 -> Richiedere a MAN: AWS Shield Standard o Advanced? Protezioni rate limiting su API CEON?
A39: 25 | B39: ='Analisi E27 — MAN'!B34 -> Gestione risorse | C39: ='Analisi E27 — MAN'!F34 -> CONFORME | D39: ='Analisi E27 — MAN'!I34 -> BASSA | E39: ='Analisi E27 — MAN'!H34 -> Verifica monitoring CPU/RAM/disco ATU su navi GNV in produzione, alert configurati.
A40: 26 | B40: ='Analisi E27 — MAN'!B35 -> Backup | C40: ='Analisi E27 — MAN'!F35 -> CONFORME | D40: ='Analisi E27 — MAN'!I35 -> BASSA | E40: ='Analisi E27 — MAN'!H35 -> Richiedere a MAN: frequenza backup CEON cloud, retention, possibilità di restore on-demand su richiesta cliente.
A41: 27 | B41: ='Analisi E27 — MAN'!B36 -> Ripristino | C41: ='Analisi E27 — MAN'!F36 -> CONFORME | D41: ='Analisi E27 — MAN'!I36 -> MEDIA | E41: ='Analisi E27 — MAN'!H36 -> Verificare con MAN: tempi RTO/RPO documentati, runbook formale di disaster recovery.
A42: 28 | B42: ='Analisi E27 — MAN'!B37 -> Alimentazione emergenza | C42: ='Analisi E27 — MAN'!F37 -> PARZIALMENTE CONFORME | D42: ='Analisi E27 — MAN'!I37 -> MEDIA | E42: ='Analisi E27 — MAN'!H37 -> Verifica nave per nave: UPS presente in ECR per alimentare mGuard + Managed Switch + EMS, autonomia adeguata, manutenzione periodica.
...
