Workbook

Sheet Analisi E27 — CAIM
A1: Analisi IACS UR E27 (sez. 4.1 + 4.2) — CAIM (NaviGate + NGBox + NGLinq + ADP/e-NP) — GNV
A2: HWG Sababa — Aprile 2026 | Fonti: NGBOX-NGLINQ Standard Configuration Guide_v.1.0.pdf (24/07/2025), NaviGate_ADP_eNP_IT_Reference_Guide.pdf, Navigate Basic Procedures for User_v.2.0.pdf (11/03/2026), NaviGate_Backup and Restore.pdf (cap. 23), NaviGate_Activation_Master (1).pdf, NAVIGATE_How_Activate_Backup_Station (1).pdf, ALTAIR.txt + File multimediali.jpeg + File multimediali (1).jpeg (documentazione installazione GNV Altair, foto postazioni primaria/backup del 05/03/2026 ore 11:37/11:38: Hostname ALTD102058/ALTD102061, IP 172.16.128.228/231, username 'rt'), GNV_Systems_2026-04-17.xlsx tab CAIM. Per i criteri di classificazione stati, vedere foglio 'Legenda'.
A3: # | B3: Controllo E27 | C3: Rif. IEC | D3: Cosa sappiamo | E3: Da dove viene l'informazione | F3: Stato | G3: Cosa manca / criticità | H3: Cosa fare | I3: Priorità
A4: FR1 — Identificazione e autenticazione
A5: 1 | B5: Identificazione utente | C5: SR 1.1 | D5: CAIM installato su 2 PC Windows dedicati (Master + Slave) per nave. Su GNV Altair: Hostname ALTD102058 (primario) e ALTD102061 (backup), entrambi con username 'rt' (username condiviso tra le due postazioni). L'accesso al NGBox richiede privilegi Administrator pieni per l'esecuzione del software. | E5: NaviGate_ADP_eNP_IT_Reference_Guide.pdf sez. 2.1 (Full Administrator Rights) ALTAIR.txt (documentazione installazione GNV Altair: ALTD102058/ALTD102061, 172.16.128.228/231, username 'rt') | F5: PARZIALMENTE CONFORME | G5: Username 'rt' condiviso tra postazione primaria e backup — account condiviso, non individuale. Non è possibile tracciare quale operatore ha eseguito un'azione. Requisito Administrator pieno applica privilegi elevati a un account condiviso. | H5: Richiedere a CAIM se il software supporta account individuali. Concordare con GNV la creazione di account individuali per ogni operatore che usa le postazioni NaviGate, con traccia degli accessi. | I5: MEDIA
A6: 2 | B6: Gestione account | C6: SR 1.3 | D6: Nessuna procedura formale di lifecycle account documentata nei manuali ricevuti. Gli utenti locali Windows sulle postazioni GNV Altair ('rt') sono gestiti presumibilmente via procedure GNV/Dastech. | E6: Inferenza dai manuali CAIM (che non trattano lifecycle account) | F6: DA VERIFICARE | G6: Manca procedura di creazione, modifica, revoca account. La gestione di 'rt' a bordo è incerta. | H6: Richiedere a Dastech/GNV chi gestisce l'account Windows 'rt' sulle postazioni Altair (e sulle altre navi). Definire procedura di lifecycle. | I6: MEDIA
A7: 3 | B7: Gestione ruoli | C7: SR 1.4 | D7: NaviGate non documenta ruoli interni all'applicazione. Il software funziona in modalità Master o Slave (architettura a 2 postazioni, solo una attiva alla volta come Master). | E7: Navigate Basic Procedures for User_v.2.0.pdf (11/03/2026) (ruoli Master/Slave) | F7: PARZIALMENTE CONFORME | G7: Il concetto di 'ruolo' esiste a livello di stazione (Master vs Slave), non di utente. Nessun modello granulare ruolo/privilegio interno. | H7: Richiedere a CAIM se esistono ruoli utente distinti nel software (es. read-only vs editor). Se no, prendere atto del limite. | I7: BASSA
A8: 4 | B8: Gestione credenziali | C8: SR 1.5 | D8: Credenziali di default pubblicate nel manuale ufficiale CAIM: NGBox Computer 'admin' / 'Ngbox_2024!' e Mikrotik Router 'admin' / 'Ngbox_2024!'. Le credenziali sono identiche per NGBox e Mikrotik e presumibilmente identiche su tutte le navi che ricevono il sistema. TeamViewer pre-installato con credenziali gestite da CAIM Support (non note a GNV). | E8: NGBOX-NGLINQ Standard Configuration Guide_v.1.0.pdf (24/07/2025) sez. 3 'Credentials' | F8: PARZIALMENTE CONFORME | G8: Le credenziali di default sono documentate in un manuale tecnico distribuito ai clienti ma non sono segrete. Se non cambiate al commissioning, forniscono accesso ad admin NGBox e Mikrotik a chiunque abbia letto il manuale. Il problema è sistemico: stesse credenziali su tutta la flotta NaviGate. Riguarda confidenzialità e autenticazione. La mitigazione è responsabilità del cliente al commissioning. | H8: 1) Verificare per ciascuna nave GNV che le credenziali di default NGBox e Mikrotik siano state cambiate al commissioning. 2) Richiedere a CAIM policy formale di change password obbligatorio al commissioning + meccanismo di conferma (es. ticket di installazione firmato). 3) Gestire centralmente le credenziali TeamViewer (se TeamViewer resta attivo) in un password manager GNV. | I8: ALTA
A9: 5 | B9: Accesso wireless | C9: SR 1.6 | D9: Architettura CAIM include WiFi attivo: il MikroTik Router ha interfaccia WiFi che serve la chiavetta NGLinq USB collegata all'ECDIS (comunicazione WiFi NGLinq↔MikroTik). Raccomandazione produttore: NGLinq entro 5 metri dal MikroTik. Il NGBox è invece collegato via LAN cablata al MikroTik. | E9: NGBOX-NGLINQ Standard Configuration Guide_v.1.0.pdf (24/07/2025) sez. 2 'Connections', sez. 4 'Network Default Configuration', sez. 6 'NGLinq' | F9: PARZIALMENTE CONFORME | G9: WiFi presente e attivo nella configurazione standard. La rete WiFi del MikroTik trasporta i dati cartografici tra NGLinq e NGBox — dati non confidenziali ma l'attaccante in range può interagire con il router se non protetto. Non documentato quale protezione WiFi (WPA2/WPA3, lunghezza chiave, rotazione) sia applicata su GNV. | H9: Richiedere a CAIM/Dastech: (1) protocollo WiFi configurato (WPA2/WPA3), (2) complessità chiave, (3) isolamento della rete WiFi MikroTik rispetto alla Ship LAN, (4) se il WiFi è mai stato disabilitato su qualche nave dove l'NGLinq non è usato. | I9: MEDIA
A10: 6 | B10: Robustezza password | C10: SR 1.7 | D10: Password di default 'Ngbox_2024!' rispetta requisiti minimi classici (8+ caratteri, maiuscole, minuscole, numeri, speciale) ma è una password pubblicata nel manuale. Nessuna policy password documentata da CAIM per l'applicazione o il sistema operativo. | E10: NGBOX-NGLINQ Standard Configuration Guide_v.1.0.pdf (24/07/2025) sez. 3 | F10: PARZIALMENTE CONFORME | G10: La stringa rispetta la complessità minima ma non la segretezza. Nessuna policy password CAIM documentata: complessità, scadenza, storia, lockout. | H10: Richiedere a CAIM policy password formale. Applicare su GNV policy password robusta via GPO/locale per account Windows 'rt' e credenziali NGBox/Mikrotik post-commissioning. | I10: MEDIA
A11: 7 | B11: Mascheratura password | C11: SR 1.10 | D11: Applicazione NaviGate desktop standard Windows. Login Windows standard maschera password. Prassi CAIM non dichiarata esplicitamente ma coerente con standard Windows. | E11: Prassi standard applicazioni Windows | F11: CONFORME | G11: Assunto coerente. Verifica visiva durante visita bordo. | H11: Verifica visiva durante visita bordo. | I11: BASSA
A12: FR2 — Controllo degli accessi e audit
A13: 8 | B13: Minimo privilegio | C13: SR 2.1 | D13: CAIM richiede esplicitamente 'Full Administrator Rights' per l'esecuzione del software: 'Restricted user accounts will cause operational failures'. L'account 'rt' su GNV Altair è quindi presumibilmente Administrator locale. | E13: NaviGate_ADP_eNP_IT_Reference_Guide.pdf sez. 2.1 'User Privileges' | F13: NON CONFORME | G13: Violazione diretta del principio del minimo privilegio: l'account utente operativo di bordo ha privilegi di Administrator pieni per esigenze applicative. Un'eventuale compromissione dell'account 'rt' darebbe accesso Administrator al PC. | H13: 1) Richiedere a CAIM se esiste una modalità di esecuzione con privilegi ridotti (es. solo admin per installazione, utente standard per esecuzione). 2) Se il requisito Administrator è strutturale, formalizzare come finding e concordare compensating controls (application whitelisting, EDR, MFA login locale). | I13: ALTA
A14: 9 | B14: Controllo wireless | C14: SR 2.2 | D14: Il MikroTik Router ha WiFi attivo per comunicazione con NGLinq (vedi item 5). Nessun controllo formale sull'uso del WiFi documentato (authorization, monitoring, enforcement). | E14: NGBOX-NGLINQ Standard Configuration Guide_v.1.0.pdf (24/07/2025) sez. 2, 4 | F14: PARZIALMENTE CONFORME | G14: WiFi attivo senza policy documentata di controllo uso, monitoring, authorization. Accesso al MikroTik come admin (credenziali default Ngbox_2024!) permetterebbe modifiche alla config WiFi. | H14: Richiedere a CAIM/Dastech: policy sul WiFi MikroTik, logging degli accessi, meccanismi di authorization (es. MAC filtering NGLinq). | I14: MEDIA
A15: 10 | B15: Dispositivi USB | C15: SR 2.3 | D15: L'architettura CAIM USA una chiavetta USB (NGLinq) come componente operativo: si collega all'ECDIS. La presenza di porte USB attive è strutturale al funzionamento del sistema. Il manuale Backup prevede scrittura su 'Pendrive folder' come opzione (USB storage usato esplicitamente). Sul NGBox e sui PC NaviGate Master/Slave le porte USB sono usate per tastiera/mouse. | E15: NGBOX-NGLINQ Standard Configuration Guide_v.1.0.pdf (24/07/2025) sez. 1, 6 (NGLinq USB) NaviGate_Backup and Restore.pdf (cap. 23) | F15: NON CONFORME | G15: USB non può essere disabilitata (NGLinq richiede USB per funzionare). Il backup può essere fatto su USB storage. Nessun whitelisting di device USB né mass storage controls documentati. L'USB del NGLinq NON è usata solo per NGLinq: una USB generica potrebbe essere inserita nella stessa porta. | H15: 1) Richiedere a CAIM se NGLinq espone un device identifier univoco verificabile. 2) Applicare hardening USB su GNV (via GPO/EDR): whitelist NGLinq, blocco USB mass storage generico. 3) Policy operativa GNV: non usare pendrive per backup (usare cartelle di rete). | I15: ALTA
A16: 11 | B16: Mobile code | C16: SR 2.4 | D16: NaviGate è applicazione desktop basata su .NET Framework 4.8. Non documentato uso di mobile code (ActiveX, Flash, JavaScript embedded). | E16: NaviGate_ADP_eNP_IT_Reference_Guide.pdf sez. 3.2 (requisito .NET 4.8) | F16: CONFORME | G16: Architettura desktop .NET non predilige mobile code insicuro. | H16: Richiedere a CAIM conferma esplicita assenza di componenti web browser embedded o mobile code. | I16: BASSA
A17: 12 | B17: Blocco sessione | C17: SR 2.5 | D17: Non documentato timeout sessione NaviGate. Sul Windows dei PC GNV Altair presumibilmente vige policy GNV standard (lock screen dopo inattività), ma non confermata. | E17: Non documentato | F17: DA VERIFICARE | G17: Timeout sessione applicativo NaviGate non documentato. Timeout OS Windows GNV da verificare. | H17: Richiedere a CAIM: timeout inattività NaviGate. Verificare con Dastech/GNV policy lock screen Windows su PC CAIM. | I17: MEDIA
A18: 13 | B18: Log eventi sicurezza | C18: SR 2.8 | D18: Nessuna informazione nei manuali CAIM su generazione log di audit (accessi, modifiche configurazione, operazioni critiche). Il sistema registra attività operativa (calcoli, rotte, pubblicazioni) ma non è chiaro se genera audit trail di sicurezza. | E18: Non documentato nei manuali CAIM | F18: DA VERIFICARE | G18: Gap di documentazione sul logging di sicurezza. Eventi registrati da NaviGate: non classificati. Su Windows, log eventi standard disponibili ma non esplicitamente integrati. | H18: Richiedere a CAIM: elenco eventi di sicurezza loggati da NaviGate e NGBox (login, logout, failed attempts, modifiche config, errori attivazione), formato, percorso storage, retention. | I18: MEDIA
A19: 14 | B19: Spazio storage log | C19: SR 2.9 | D19: Non documentato. Spazio per data archive applicativo: 5 GB minimi (dati cartografici e pubblicazioni), non log. | E19: NaviGate_ADP_eNP_IT_Reference_Guide.pdf sez. 3.2 (5 GB disk space) | F19: DA VERIFICARE | G19: Storage log, retention, rotazione non documentati. | H19: Richiedere a CAIM. | I19: BASSA
A20: 15 | B20: Failure del logging | C20: SR 2.10 | D20: Non documentato. | E20: Non documentato | F20: DA VERIFICARE | G20: Comportamento in caso di failure del logging non documentato. | H20: Richiedere a CAIM. | I20: BASSA
A21: 16 | B21: Timestamp nei log | C21: SR 2.11 | D21: Non documentato. Windows sincronizza tipicamente con W32Time: per PC dedicati CAIM dipende dalla configurazione GNV/Dastech. | E21: Non documentato | F21: DA VERIFICARE | G21: Presenza e sincronizzazione timestamp non confermate. | H21: Verificare con Dastech se i PC CAIM sincronizzano con NTP interno GNV. | I21: BASSA
A22: FR3 — Integrità del sistema
A23: 17 | B23: Integrità comunicazioni | C23: SR 3.1 | D23: Traffico principale verso cloud in HTTPS (TLS 1.2+ richiesto esplicitamente come minimo). Configurazione firewall: maritimegate.net:443 (nGateway.exe), www.admiralty.co.uk:443, enavigator.ukho.gov.uk:443. HTTP fallback (porta 80) documentato come opzione configurabile: 'replace https://maritimegate.net with http://maritimegate.net'. FTP su porta 21 (passive) per e-NP, porte 20-21 per adpactivation.ukho.gov.uk. | E23: NGBOX-NGLINQ Standard Configuration Guide_v.1.0.pdf (24/07/2025) sez. 7.3 NaviGate_ADP_eNP_IT_Reference_Guide.pdf sez. 3-6 | F23: PARZIALMENTE CONFORME | G23: HTTPS default OK. Problema: HTTP fallback documentato ESPLICITAMENTE come opzione permessa (se la nave non supporta HTTPS). FTP per e-NP e attivazione ADP sono protocolli in chiaro per definizione. | H23: 1) Verificare per ciascuna nave GNV che sia effettivamente in uso HTTPS e non il fallback HTTP. 2) Richiedere a CAIM integrità sugli aggiornamenti pubblicazioni scaricati via FTP (firma digitale, hash). 3) Formalizzare policy GNV: HTTP mai usato come fallback. | I23: ALTA
A24: 18 | B24: Protezione malware | C24: SR 3.2 | D24: NGBox gira Windows con 'pre-configured through Clonezilla'. Il manuale raccomanda solo Windows supportati da Microsoft. Nessuna indicazione esplicita su antivirus: non è richiesto né escluso. | E24: NGBOX-NGLINQ Standard Configuration Guide_v.1.0.pdf (24/07/2025) sez. 1 NaviGate_ADP_eNP_IT_Reference_Guide.pdf sez. 2.1 | F24: DA VERIFICARE | G24: Policy antivirus CAIM non dichiarata. Compatibilità CAIM con antivirus/EDR enterprise non documentata (possibili falsi positivi su nGateway.exe). | H24: Richiedere a CAIM: antivirus/EDR supportati, eventuali esclusioni richieste per processi CAIM (NaviGate.exe, nGateway.exe, nGatewayManager.exe). | I24: ALTA
A25: 19 | B25: Test sicurezza | C25: SR 3.3 | D25: Nessuna informazione su test di sicurezza o certificazioni cybersecurity del prodotto nei manuali ricevuti. | E25: Non documentato | F25: DA VERIFICARE | G25: Assenza di evidenze di penetration test, vulnerability assessment, type approval cyber. | H25: Richiedere a CAIM: evidenze di test di sicurezza, certificazioni RINA/DNV/BV. Pianificare FAT/SAT cyber per installazioni GNV. | I25: MEDIA
A26: 20 | B26: Stato sicuro (fail-safe) | C26: SR 3.4 | D26: CAIM è sistema di supporto alla navigazione (gestione pubblicazioni digitali e pianificazione), non sistema di controllo attivo. Architettura ridondante Master + Slave mitiga il rischio di indisponibilità: se una postazione si pianta, l'altra copre. Il manuale Basic Procedures formalizza la procedura di switch Master↔Slave. | E26: Navigate Basic Procedures for User_v.2.0.pdf (11/03/2026) (architettura Master/Slave) GNV_Systems tab CAIM | F26: CONFORME | G26: Sistema passivo + ridondanza. Nessun impatto safety-critical diretto in caso di attacco. | H26: Formalizzare procedura switch Master/Slave per equipaggio GNV. | I26: BASSA
A27: FR4 — Confidenzialità dei dati
A28: 21 | B28: Protezione dati | C28: SR 4.1 | D28: Dati cartografici e pubblicazioni nautiche non sono confidenziali. Dati confidenziali potenziali: credenziali (utente 'rt', credenziali NGBox, Mikrotik, TeamViewer), certificati attivazione, configurazione nave. Cifratura at-rest sui PC NaviGate non documentata. | E28: Inferenza dall'architettura documentata | F28: PARZIALMENTE CONFORME | G28: Cifratura storage non documentata (no BitLocker dichiarato). Le credenziali e i codici di attivazione sono potenzialmente in chiaro sul disco. | H28: Applicare su GNV cifratura disco (BitLocker) sulle postazioni NaviGate. Richiedere a CAIM se BitLocker è supportato/testato. | I28: MEDIA
A29: 22 | B29: Crittografia | C29: SR 4.3 | D29: Requisito esplicito TLS 1.2 minimo per comunicazioni NaviGate↔maritimegate.net. Il manuale include guida dettagliata per abilitare TLS 1.2 anche su Windows 7. Suite di cifratura e versione massima supportata non dettagliate. | E29: NaviGate_ADP_eNP_IT_Reference_Guide.pdf sez. 3.4 'TLS 1.2 Configuration Guide' | F29: CONFORME | G29: Minimo TLS 1.2 OK rispetto agli standard attuali. TLS 1.3 non dichiarato esplicitamente. | H29: Richiedere a CAIM: supporto TLS 1.3, suite di cifratura consigliate. | I29: BASSA
A30: FR6 — Risposta agli eventi
A31: 23 | B31: Accessibilità log audit | C31: SR 6.1 | D31: Dipendenza diretta da item 13 (log assenti/non documentati). | E31: Vedi item 13 | F31: DA VERIFICARE | G31: Accessibilità log a utenti autorizzati non documentata. | H31: Vedi item 13. | I31: BASSA
A32: FR7 — Disponibilità delle risorse
A33: 24 | B33: Protezione DoS | C33: SR 7.1 | D33: Architettura ridondante Master + Slave mitiga DoS (se una postazione si pianta, l'altra copre). Protezioni DoS a livello applicativo non documentate. | E33: Navigate Basic Procedures for User_v.2.0.pdf (11/03/2026) (Master/Slave) | F33: PARZIALMENTE CONFORME | G33: Ridondanza HW sì, protezioni DoS applicative non documentate. Il MikroTik router è punto singolo di failure per NGBox↔NGLinq. | H33: Richiedere a CAIM: comportamento NaviGate sotto DoS, resilienza MikroTik. | I33: BASSA
A34: 25 | B34: Gestione risorse | C34: SR 7.2 | D34: Requisiti HW specifici: processor i5 quad-core, 8 GB RAM min, 16 GB RAM per Windows 10+. Gestione risorse interne applicativa non documentata. | E34: NaviGate_ADP_eNP_IT_Reference_Guide.pdf sez. 3.2 | F34: DA VERIFICARE | G34: Limiti interni applicativi non documentati. | H34: Richiedere a CAIM. | I34: BASSA
A35: 26 | B35: Backup | C35: SR 7.3 | D35: Procedura backup manuale documentata: funzionalità 'Backup' nel menu System di NaviGate. Backup include NaviGate settings (sottoscrizioni, cataloghi, ship model), SENC, AIO, Paper charts, Books, Weather, Navarea, Piracy, NP234, Routes. Destinazione: cartella locale o Pendrive USB. Backup manuale, non schedulato. INTEGRAZIONE 27/04/2026: procedura backup manuale dettagliata in NAVIGATE_How_Activate_Backup_Station (1).pdf (2 pagine): 1) backup dal PC primario via menu System → Backup → scelta destinazione (cartella locale o pendrive USB), 2) copia del backup file sul PC backup, 3) installazione NaviGate sul PC backup, 4) Tasks → Active product → Activate Backup Station → selezione del backup file. Il PC backup viene attivato con lo stesso contract del primario, senza consumo di nuova licenza. | E35: NaviGate_Backup and Restore.pdf (cap. 23) NaviGate_Activation_Master (1).pdf NAVIGATE_How_Activate_Backup_Station (1).pdf | F35: PARZIALMENTE CONFORME | G35: Backup disponibile ma MANUALE (deve essere eseguito dall'operatore). Nessuna schedulazione automatica documentata. Raccomandazione backup su Pendrive è in tensione con item 10 (rischio USB). | H35: 1) Definire policy GNV per frequenza e destinazione backup (non usare pendrive, usare cartella di rete dedicata). 2) Richiedere a CAIM se esiste scheduling automatico del backup. | I35: MEDIA
A36: 27 | B36: Ripristino | C36: SR 7.4 | D36: Procedura 'Restore' documentata nel menu System. Procedura 'Activate Backup Station' disponibile: se il Master si pianta, il backup file può essere usato per attivare lo Slave con lo stesso contract (senza consumare nuova licenza). I passi sono documentati nei manuali forniti. | E36: NaviGate_Backup and Restore.pdf (cap. 23) cap. 23.B NAVIGATE_How_Activate_Backup_Station (1).pdf | F36: CONFORME | G36: Procedura di recovery documentata. RTO/RPO non quantificati. | H36: Definire RTO/RPO con CAIM e Dastech. Testare la procedura di recovery almeno una volta per nave. | I36: BASSA
A37: 28 | B37: Alimentazione emergenza | C37: SR 7.5 | D37: Non documentato nei manuali CAIM. Alimentazione NGBox: DC 9-36V / AC Power Adapter incluso. Collegamento a UPS di bordo da verificare nelle installazioni GNV. | E37: NGBOX-NGLINQ Standard Configuration Guide_v.1.0.pdf (24/07/2025) sez. 2 (power) | F37: DA VERIFICARE | G37: Collegamento UPS per PC CAIM/NGBox/Mikrotik non documentato. | H37: Verificare su Cable Diagram / durante visita bordo se le postazioni CAIM sono su UPS. | I37: MEDIA
A38: 29 | B38: Configurazione rete | C38: SR 7.6 | D38: Configurazione di rete documentata: NGBox 172.16.10.20 (default, ma GNV Altair usa 172.16.128.228/231 — configurazione custom GNV), Mikrotik LAN 172.16.10.1, NGLinq WiFi 172.16.11.30. Firewall ship-side: whitelist specifica documentata (IP UKHO, porte, URL). Mikrotik gestito da CAIM. | E38: NGBOX-NGLINQ Standard Configuration Guide_v.1.0.pdf (24/07/2025) sez. 4 ALTAIR.txt (documentazione installazione GNV Altair: ALTD102058/ALTD102061, 172.16.128.228/231, username 'rt') NaviGate_ADP_eNP_IT_Reference_Guide.pdf | F38: PARZIALMENTE CONFORME | G38: Configurazione di rete documentata a livello di prodotto. Per GNV: VLAN di collocazione non chiarite. Il Mikrotik è gestito da CAIM (credenziali default), separazione di responsabilità tra CAIM/Dastech/GNV da formalizzare. | H38: 1) Chiarire con Dastech: su quale VLAN sono i PC NaviGate e il NGBox. 2) Definire chi gestisce il Mikrotik (CAIM? Dastech? GNV?). 3) Cambiare credenziali default MikroTik e documentare nuovo owner. | I38: ALTA
A39: 30 | B39: Hardening | C39: SR 7.7 | D39: Alcune indicazioni di hardening presenti nei manuali CAIM: PC dedicati esclusivamente a navigazione (no office, no email, no web browsing generico), no Thin Client, no Virtual Machine, no Server, no PC condivisi, esclusione cloud sync (OneDrive/DropBox/iCloud) dalle cartelle dati. Ma manca guida hardening completa per Mikrotik e NGBox. | E39: NaviGate_ADP_eNP_IT_Reference_Guide.pdf sez. 2.1, 2.2 NGBOX-NGLINQ Standard Configuration Guide_v.1.0.pdf (24/07/2025) | F39: PARZIALMENTE CONFORME | G39: Best practice dichiarate per i PC NaviGate Master/Slave. Mancanti: hardening Mikrotik (cambio credenziali, disabilitazione servizi non necessari), hardening NGBox (oltre alle raccomandazioni PC). | H39: Richiedere a CAIM hardening guide formale completa (NaviGate + NGBox + Mikrotik). Applicare su GNV. | I39: MEDIA
A40: Sez. 4.2 — Additional security capabilities (reti untrusted)
...

Sheet Riepilogo
A1: Riepilogo — Analisi E27 CAIM (NaviGate + NGBox + NGLinq + ADP/e-NP)
A3: CONTEGGIO AUTOMATICO STATO (aggiornamento dinamico dal foglio Analisi)
A4: # | B4: Stato | C4: Conteggio | D4: Totale | E4: Percentuale
A5: 1 | B5: CONFORME | C5: =COUNTIF('Analisi E27 — CAIM'!$F$4:$F$66,"CONFORME") -> 6 | D5: =COUNTIF('Analisi E27 — CAIM'!$F$4:$F$66,"CONFORME")+COUNTIF('Analisi E27 — CAIM'!$F$4:$F$66,"PARZIALMENTE CONFORME")+COUNTIF('Analisi E27 — CAIM'!$F$4:$F$66,"NON CONFORME")+COUNTIF('Analisi E27 — CAIM'!$F$4:$F$66,"DA VERIFICARE")+COUNTIF('Analisi E27 — CAIM'!$F$4:$F$66,"N/A") -> 51 | E5: =IF(D5=0,"",C5/D5) -> 0.11764706
A6: 2 | B6: PARZIALMENTE CONFORME | C6: =COUNTIF('Analisi E27 — CAIM'!$F$4:$F$66,"PARZIALMENTE CONFORME") -> 20 | D6: =COUNTIF('Analisi E27 — CAIM'!$F$4:$F$66,"CONFORME")+COUNTIF('Analisi E27 — CAIM'!$F$4:$F$66,"PARZIALMENTE CONFORME")+COUNTIF('Analisi E27 — CAIM'!$F$4:$F$66,"NON CONFORME")+COUNTIF('Analisi E27 — CAIM'!$F$4:$F$66,"DA VERIFICARE")+COUNTIF('Analisi E27 — CAIM'!$F$4:$F$66,"N/A") -> 51 | E6: =IF(D6=0,"",C6/D6) -> 0.39215686
A7: 3 | B7: NON CONFORME | C7: =COUNTIF('Analisi E27 — CAIM'!$F$4:$F$66,"NON CONFORME") -> 4 | D7: =COUNTIF('Analisi E27 — CAIM'!$F$4:$F$66,"CONFORME")+COUNTIF('Analisi E27 — CAIM'!$F$4:$F$66,"PARZIALMENTE CONFORME")+COUNTIF('Analisi E27 — CAIM'!$F$4:$F$66,"NON CONFORME")+COUNTIF('Analisi E27 — CAIM'!$F$4:$F$66,"DA VERIFICARE")+COUNTIF('Analisi E27 — CAIM'!$F$4:$F$66,"N/A") -> 51 | E7: =IF(D7=0,"",C7/D7) -> 0.078431373
A8: 4 | B8: DA VERIFICARE | C8: =COUNTIF('Analisi E27 — CAIM'!$F$4:$F$66,"DA VERIFICARE") -> 21 | D8: =COUNTIF('Analisi E27 — CAIM'!$F$4:$F$66,"CONFORME")+COUNTIF('Analisi E27 — CAIM'!$F$4:$F$66,"PARZIALMENTE CONFORME")+COUNTIF('Analisi E27 — CAIM'!$F$4:$F$66,"NON CONFORME")+COUNTIF('Analisi E27 — CAIM'!$F$4:$F$66,"DA VERIFICARE")+COUNTIF('Analisi E27 — CAIM'!$F$4:$F$66,"N/A") -> 51 | E8: =IF(D8=0,"",C8/D8) -> 0.41176471
A9: 5 | B9: N/A | C9: =COUNTIF('Analisi E27 — CAIM'!$F$4:$F$66,"N/A") -> 0 | D9: =COUNTIF('Analisi E27 — CAIM'!$F$4:$F$66,"CONFORME")+COUNTIF('Analisi E27 — CAIM'!$F$4:$F$66,"PARZIALMENTE CONFORME")+COUNTIF('Analisi E27 — CAIM'!$F$4:$F$66,"NON CONFORME")+COUNTIF('Analisi E27 — CAIM'!$F$4:$F$66,"DA VERIFICARE")+COUNTIF('Analisi E27 — CAIM'!$F$4:$F$66,"N/A") -> 51 | E9: =IF(D9=0,"",C9/D9) -> 0
B10: TOTALE | C10: =SUM(C5:C9) -> 51
A12: DETTAGLIO PER ITEM (stato e priorità aggiornati automaticamente dal foglio Analisi)
A13: Item | B13: Controllo | C13: Stato | D13: Priorità | E13: Cosa fare
A14: Sezione 4.1 — System Requirements (30 controlli base)
A15: 1 | B15: ='Analisi E27 — CAIM'!B5 -> Identificazione utente | C15: ='Analisi E27 — CAIM'!F5 -> PARZIALMENTE CONFORME | D15: ='Analisi E27 — CAIM'!I5 -> MEDIA | E15: ='Analisi E27 — CAIM'!H5 -> Richiedere a CAIM se il software supporta account individuali. Concordare con GNV la creazione di account individuali per ogni operatore che usa le postazioni NaviGate, con traccia degli accessi.
A16: 2 | B16: ='Analisi E27 — CAIM'!B6 -> Gestione account | C16: ='Analisi E27 — CAIM'!F6 -> DA VERIFICARE | D16: ='Analisi E27 — CAIM'!I6 -> MEDIA | E16: ='Analisi E27 — CAIM'!H6 -> Richiedere a Dastech/GNV chi gestisce l'account Windows 'rt' sulle postazioni Altair (e sulle altre navi). Definire procedura di lifecycle.
A17: 3 | B17: ='Analisi E27 — CAIM'!B7 -> Gestione ruoli | C17: ='Analisi E27 — CAIM'!F7 -> PARZIALMENTE CONFORME | D17: ='Analisi E27 — CAIM'!I7 -> BASSA | E17: ='Analisi E27 — CAIM'!H7 -> Richiedere a CAIM se esistono ruoli utente distinti nel software (es. read-only vs editor). Se no, prendere atto del limite.
A18: 4 | B18: ='Analisi E27 — CAIM'!B8 -> Gestione credenziali | C18: ='Analisi E27 — CAIM'!F8 -> PARZIALMENTE CONFORME | D18: ='Analisi E27 — CAIM'!I8 -> ALTA | E18: ='Analisi E27 — CAIM'!H8 -> 1) Verificare per ciascuna nave GNV che le credenziali di default NGBox e Mikrotik siano state cambiate al commissioning. 2) Richiedere a CAIM policy formale di change password obbligatorio al commissioning + meccanismo di conferma (es. ticket di installazione firmato). 3) Gestire centralmente le credenziali TeamViewer (se TeamViewer resta attivo) in un password manager GNV.
A19: 5 | B19: ='Analisi E27 — CAIM'!B9 -> Accesso wireless | C19: ='Analisi E27 — CAIM'!F9 -> PARZIALMENTE CONFORME | D19: ='Analisi E27 — CAIM'!I9 -> MEDIA | E19: ='Analisi E27 — CAIM'!H9 -> Richiedere a CAIM/Dastech: (1) protocollo WiFi configurato (WPA2/WPA3), (2) complessità chiave, (3) isolamento della rete WiFi MikroTik rispetto alla Ship LAN, (4) se il WiFi è mai stato disabilitato su qualche nave dove l'NGLinq non è usato.
A20: 6 | B20: ='Analisi E27 — CAIM'!B10 -> Robustezza password | C20: ='Analisi E27 — CAIM'!F10 -> PARZIALMENTE CONFORME | D20: ='Analisi E27 — CAIM'!I10 -> MEDIA | E20: ='Analisi E27 — CAIM'!H10 -> Richiedere a CAIM policy password formale. Applicare su GNV policy password robusta via GPO/locale per account Windows 'rt' e credenziali NGBox/Mikrotik post-commissioning.
A21: 7 | B21: ='Analisi E27 — CAIM'!B11 -> Mascheratura password | C21: ='Analisi E27 — CAIM'!F11 -> CONFORME | D21: ='Analisi E27 — CAIM'!I11 -> BASSA | E21: ='Analisi E27 — CAIM'!H11 -> Verifica visiva durante visita bordo.
A22: 8 | B22: ='Analisi E27 — CAIM'!B13 -> Minimo privilegio | C22: ='Analisi E27 — CAIM'!F13 -> NON CONFORME | D22: ='Analisi E27 — CAIM'!I13 -> ALTA | E22: ='Analisi E27 — CAIM'!H13 -> 1) Richiedere a CAIM se esiste una modalità di esecuzione con privilegi ridotti (es. solo admin per installazione, utente standard per esecuzione). 2) Se il requisito Administrator è strutturale, formalizzare come finding e concordare compensating controls (application whitelisting, EDR, MFA login locale).
A23: 9 | B23: ='Analisi E27 — CAIM'!B14 -> Controllo wireless | C23: ='Analisi E27 — CAIM'!F14 -> PARZIALMENTE CONFORME | D23: ='Analisi E27 — CAIM'!I14 -> MEDIA | E23: ='Analisi E27 — CAIM'!H14 -> Richiedere a CAIM/Dastech: policy sul WiFi MikroTik, logging degli accessi, meccanismi di authorization (es. MAC filtering NGLinq).
A24: 10 | B24: ='Analisi E27 — CAIM'!B15 -> Dispositivi USB | C24: ='Analisi E27 — CAIM'!F15 -> NON CONFORME | D24: ='Analisi E27 — CAIM'!I15 -> ALTA | E24: ='Analisi E27 — CAIM'!H15 -> 1) Richiedere a CAIM se NGLinq espone un device identifier univoco verificabile. 2) Applicare hardening USB su GNV (via GPO/EDR): whitelist NGLinq, blocco USB mass storage generico. 3) Policy operativa GNV: non usare pendrive per backup (usare cartelle di rete).
A25: 11 | B25: ='Analisi E27 — CAIM'!B16 -> Mobile code | C25: ='Analisi E27 — CAIM'!F16 -> CONFORME | D25: ='Analisi E27 — CAIM'!I16 -> BASSA | E25: ='Analisi E27 — CAIM'!H16 -> Richiedere a CAIM conferma esplicita assenza di componenti web browser embedded o mobile code.
A26: 12 | B26: ='Analisi E27 — CAIM'!B17 -> Blocco sessione | C26: ='Analisi E27 — CAIM'!F17 -> DA VERIFICARE | D26: ='Analisi E27 — CAIM'!I17 -> MEDIA | E26: ='Analisi E27 — CAIM'!H17 -> Richiedere a CAIM: timeout inattività NaviGate. Verificare con Dastech/GNV policy lock screen Windows su PC CAIM.
A27: 13 | B27: ='Analisi E27 — CAIM'!B18 -> Log eventi sicurezza | C27: ='Analisi E27 — CAIM'!F18 -> DA VERIFICARE | D27: ='Analisi E27 — CAIM'!I18 -> MEDIA | E27: ='Analisi E27 — CAIM'!H18 -> Richiedere a CAIM: elenco eventi di sicurezza loggati da NaviGate e NGBox (login, logout, failed attempts, modifiche config, errori attivazione), formato, percorso storage, retention.
A28: 14 | B28: ='Analisi E27 — CAIM'!B19 -> Spazio storage log | C28: ='Analisi E27 — CAIM'!F19 -> DA VERIFICARE | D28: ='Analisi E27 — CAIM'!I19 -> BASSA | E28: ='Analisi E27 — CAIM'!H19 -> Richiedere a CAIM.
A29: 15 | B29: ='Analisi E27 — CAIM'!B20 -> Failure del logging | C29: ='Analisi E27 — CAIM'!F20 -> DA VERIFICARE | D29: ='Analisi E27 — CAIM'!I20 -> BASSA | E29: ='Analisi E27 — CAIM'!H20 -> Richiedere a CAIM.
A30: 16 | B30: ='Analisi E27 — CAIM'!B21 -> Timestamp nei log | C30: ='Analisi E27 — CAIM'!F21 -> DA VERIFICARE | D30: ='Analisi E27 — CAIM'!I21 -> BASSA | E30: ='Analisi E27 — CAIM'!H21 -> Verificare con Dastech se i PC CAIM sincronizzano con NTP interno GNV.
A31: 17 | B31: ='Analisi E27 — CAIM'!B23 -> Integrità comunicazioni | C31: ='Analisi E27 — CAIM'!F23 -> PARZIALMENTE CONFORME | D31: ='Analisi E27 — CAIM'!I23 -> ALTA | E31: ='Analisi E27 — CAIM'!H23 -> 1) Verificare per ciascuna nave GNV che sia effettivamente in uso HTTPS e non il fallback HTTP. 2) Richiedere a CAIM integrità sugli aggiornamenti pubblicazioni scaricati via FTP (firma digitale, hash). 3) Formalizzare policy GNV: HTTP mai usato come fallback.
A32: 18 | B32: ='Analisi E27 — CAIM'!B24 -> Protezione malware | C32: ='Analisi E27 — CAIM'!F24 -> DA VERIFICARE | D32: ='Analisi E27 — CAIM'!I24 -> ALTA | E32: ='Analisi E27 — CAIM'!H24 -> Richiedere a CAIM: antivirus/EDR supportati, eventuali esclusioni richieste per processi CAIM (NaviGate.exe, nGateway.exe, nGatewayManager.exe).
A33: 19 | B33: ='Analisi E27 — CAIM'!B25 -> Test sicurezza | C33: ='Analisi E27 — CAIM'!F25 -> DA VERIFICARE | D33: ='Analisi E27 — CAIM'!I25 -> MEDIA | E33: ='Analisi E27 — CAIM'!H25 -> Richiedere a CAIM: evidenze di test di sicurezza, certificazioni RINA/DNV/BV. Pianificare FAT/SAT cyber per installazioni GNV.
A34: 20 | B34: ='Analisi E27 — CAIM'!B26 -> Stato sicuro (fail-safe) | C34: ='Analisi E27 — CAIM'!F26 -> CONFORME | D34: ='Analisi E27 — CAIM'!I26 -> BASSA | E34: ='Analisi E27 — CAIM'!H26 -> Formalizzare procedura switch Master/Slave per equipaggio GNV.
A35: 21 | B35: ='Analisi E27 — CAIM'!B28 -> Protezione dati | C35: ='Analisi E27 — CAIM'!F28 -> PARZIALMENTE CONFORME | D35: ='Analisi E27 — CAIM'!I28 -> MEDIA | E35: ='Analisi E27 — CAIM'!H28 -> Applicare su GNV cifratura disco (BitLocker) sulle postazioni NaviGate. Richiedere a CAIM se BitLocker è supportato/testato.
A36: 22 | B36: ='Analisi E27 — CAIM'!B29 -> Crittografia | C36: ='Analisi E27 — CAIM'!F29 -> CONFORME | D36: ='Analisi E27 — CAIM'!I29 -> BASSA | E36: ='Analisi E27 — CAIM'!H29 -> Richiedere a CAIM: supporto TLS 1.3, suite di cifratura consigliate.
A37: 23 | B37: ='Analisi E27 — CAIM'!B31 -> Accessibilità log audit | C37: ='Analisi E27 — CAIM'!F31 -> DA VERIFICARE | D37: ='Analisi E27 — CAIM'!I31 -> BASSA | E37: ='Analisi E27 — CAIM'!H31 -> Vedi item 13.
A38: 24 | B38: ='Analisi E27 — CAIM'!B33 -> Protezione DoS | C38: ='Analisi E27 — CAIM'!F33 -> PARZIALMENTE CONFORME | D38: ='Analisi E27 — CAIM'!I33 -> BASSA | E38: ='Analisi E27 — CAIM'!H33 -> Richiedere a CAIM: comportamento NaviGate sotto DoS, resilienza MikroTik.
A39: 25 | B39: ='Analisi E27 — CAIM'!B34 -> Gestione risorse | C39: ='Analisi E27 — CAIM'!F34 -> DA VERIFICARE | D39: ='Analisi E27 — CAIM'!I34 -> BASSA | E39: ='Analisi E27 — CAIM'!H34 -> Richiedere a CAIM.
A40: 26 | B40: ='Analisi E27 — CAIM'!B35 -> Backup | C40: ='Analisi E27 — CAIM'!F35 -> PARZIALMENTE CONFORME | D40: ='Analisi E27 — CAIM'!I35 -> MEDIA | E40: ='Analisi E27 — CAIM'!H35 -> 1) Definire policy GNV per frequenza e destinazione backup (non usare pendrive, usare cartella di rete dedicata). 2) Richiedere a CAIM se esiste scheduling automatico del backup.
A41: 27 | B41: ='Analisi E27 — CAIM'!B36 -> Ripristino | C41: ='Analisi E27 — CAIM'!F36 -> CONFORME | D41: ='Analisi E27 — CAIM'!I36 -> BASSA | E41: ='Analisi E27 — CAIM'!H36 -> Definire RTO/RPO con CAIM e Dastech. Testare la procedura di recovery almeno una volta per nave.
A42: 28 | B42: ='Analisi E27 — CAIM'!B37 -> Alimentazione emergenza | C42: ='Analisi E27 — CAIM'!F37 -> DA VERIFICARE | D42: ='Analisi E27 — CAIM'!I37 -> MEDIA | E42: ='Analisi E27 — CAIM'!H37 -> Verificare su Cable Diagram / durante visita bordo se le postazioni CAIM sono su UPS.
...

Sheet Legenda
A1: Legenda — Criteri di classificazione stati e priorità (IACS UR E27)
A4: Criteri di classificazione STATO
A5: Stato | B5: Quando si assegna | C5: Requisiti minimi
A6: CONFORME | B6: Il controllo è pienamente implementato dal fornitore e verificabile dalle fonti documentali ricevute. Nessun gap significativo rispetto al requisito E27. Può includere piccole verifiche residue (es. verifica visiva, test operativo) ma l'evidenza documentale è sufficiente a dichiarare la conformità. | C6: Almeno UNA delle seguenti condizioni: (a) Documentazione di prodotto del fornitore che descrive esplicitamente l'implementazione. (b) Certificazione di terze parti applicabile al controllo (es. ISO 27001 per controlli di information security management). (c) Standard tecnico implicito nell'architettura (es. TLS implicitamente garantisce integrità crittografica). (d) Evidenza fisica/operativa raccolta durante visita bordo o call tecnica.
A7: PARZIALMENTE CONFORME | B7: Il controllo è parzialmente implementato o documentato. Esistono evidenze concrete dell'implementazione ma con gap noti: documentazione incompleta, configurazione dichiarata ma non verificata, alcuni aspetti coperti e altri no, oppure il controllo si basa su un'assunzione plausibile ma non confermata. È la classificazione più comune per sistemi con documentazione parziale. | C7: TIPICAMENTE UNA delle seguenti: (a) Documentazione di prodotto copre l'aspetto MA con gap (es. 'usa TLS' senza specificare versione/suite). (b) Esiste implementazione architetturale MA manca documento formale (es. defence in depth presente ma non formalizzato). (c) Il controllo è coperto per un sottoinsieme delle navi/configurazioni MA non per tutte. (d) Standard di prassi implicito senza conferma esplicita del fornitore. (e) Mitigazione esiste lato cliente ma non integrata nel prodotto del fornitore.
A8: NON CONFORME | B8: Il controllo NON è implementato o è implementato in modo palesemente insufficiente rispetto al requisito E27. Esiste evidenza documentale o tecnica concreta del gap. Non è una mancanza di informazioni (quella va in DA VERIFICARE) ma una evidenza concreta di non conformità. | C8: TIPICAMENTE UNA delle seguenti: (a) Il fornitore dichiara esplicitamente una pratica non conforme (es. password default pubblicate nel manuale, USB strutturalmente necessari, full admin rights mandatory). (b) Architettura con elementi in chiaro non cifrati che il requisito E27 considera necessari cifrare. (c) Assenza di un meccanismo di sicurezza che il requisito richiede esplicitamente (es. MFA sui canali untrusted). (d) Canale di accesso remoto attivo senza controlli di approvazione/logging documentati (es. TeamViewer pre-installato).
A9: DA VERIFICARE | B9: Informazione insufficiente per classificare. Il controllo potrebbe essere conforme, parziale o non conforme, ma i documenti ricevuti non permettono di decidere. È diverso da 'non conforme': qui manca l'informazione, lì c'è evidenza negativa. | C9: TIPICAMENTE UNA delle seguenti: (a) Aspetto non trattato in nessun documento ricevuto (silenzio documentale). (b) Controllo che richiede dialogo diretto con il fornitore (IAM dettagliato, policy interne). (c) Controllo operativo che richiede verifica a bordo (presenza antivirus, UPS, wireless hardware). (d) Controllo per il quale il fornitore rimanda al cliente senza specifica (es. 'da configurare a cura del cliente' senza dettagli). Obiettivo: risolvere questi item con mail/call mirate al fornitore o verifica a bordo.
